Workbook

Sheet MASTER
A1: Study Code | B1: Age Range | C1: Gender | D1: Ancestry | E1: Collection Date | F1: Freeze Date | G1: Freeze time | H1: CDI Location | I1: NIH Location | J1: Max Planck Location | K1: Additional Cryovial? | L1: Cryovial Location (10x10) | M1: Estimated Volume Remaining (mL) | N1: Additional Comments
A2: =IF(COUNTA($B2:$E2,$K2)=0,"",IF(AND($B2<>"",$C2<>"",$D2<>"",$E2<>""),"TXS"&TEXT(COUNTIFS($B$2:$B2,"<>",$C$2:$C2,"<>",$D$2:$D2,"<>",$E$2:$E2,"<>"),"00000"),"")) | H2: =IF(NOT(AND($B2<>"",$C2<>"",$D2<>"",$E2<>"")),"",IF($A2="","","CDI plate "&INT((VALUE(RIGHT($A2,5))-1)/96)+1&": "&CHAR(65+INT(MOD(VALUE(RIGHT($A2,5))-1,96)/12))&(MOD(VALUE(RIGHT($A2,5))-1,12)+1))) | I2: =IF(NOT(AND($B2<>"",$C2<>"",$D2<>"",$E2<>"")),"",IF($A2="","","NIH plate "&INT((VALUE(RIGHT($A2,5))-1)/96)+1&": "&CHAR(65+INT(MOD(VALUE(RIGHT($A2,5))-1,96)/12))&(MOD(VALUE(RIGHT($A2,5))-1,12)+1))) | J2: =IF(NOT(AND($B2<>"",$C2<>"",$D2<>"",$E2<>"")),"",IF($A2="","","Max Planck plate "&INT((VALUE(RIGHT($A2,5))-1)/96)+1&": "&CHAR(65+INT(MOD(VALUE(RIGHT($A2,5))-1,96)/12))&(MOD(VALUE(RIGHT($A2,5))-1,12)+1))) | L2: =IF(OR(NOT(AND($B2<>"",$C2<>"",$D2<>"",$E2<>"")),$A2="",$K2<>"Yes"),"",IF($L2<>"",$L2,INDEX(SETUP!$I$1:$I$2000,MATCH(TRUE,SETUP!$J$1:$J$2000,0)+COUNTIFS($A$2:$A2,"<>",$K$2:$K2,"Yes",$L$2:$L2,"")-1)))
A3: =IF(COUNTA($B3:$E3,$K3)=0,"",IF(AND($B3<>"",$C3<>"",$D3<>"",$E3<>""),"TXS"&TEXT(COUNTIFS($B$2:$B3,"<>",$C$2:$C3,"<>",$D$2:$D3,"<>",$E$2:$E3,"<>"),"00000"),"")) | H3: =IF(NOT(AND($B3<>"",$C3<>"",$D3<>"",$E3<>"")),"",IF($A3="","","CDI plate "&INT((VALUE(RIGHT($A3,5))-1)/96)+1&": "&CHAR(65+INT(MOD(VALUE(RIGHT($A3,5))-1,96)/12))&(MOD(VALUE(RIGHT($A3,5))-1,12)+1))) | I3: =IF(NOT(AND($B3<>"",$C3<>"",$D3<>"",$E3<>"")),"",IF($A3="","","NIH plate "&INT((VALUE(RIGHT($A3,5))-1)/96)+1&": "&CHAR(65+INT(MOD(VALUE(RIGHT($A3,5))-1,96)/12))&(MOD(VALUE(RIGHT($A3,5))-1,12)+1))) | J3: =IF(NOT(AND($B3<>"",$C3<>"",$D3<>"",$E3<>"")),"",IF($A3="","","Max Planck plate "&INT((VALUE(RIGHT($A3,5))-1)/96)+1&": "&CHAR(65+INT(MOD(VALUE(RIGHT($A3,5))-1,96)/12))&(MOD(VALUE(RIGHT($A3,5))-1,12)+1))) | L3: =IF(OR(NOT(AND($B3<>"",$C3<>"",$D3<>"",$E3<>"")),$A3="",$K3<>"Yes"),"",IF($L3<>"",$L3,INDEX(SETUP!$I$1:$I$2000,MATCH(TRUE,SETUP!$J$1:$J$2000,0)+COUNTIFS($A$2:$A3,"<>",$K$2:$K3,"Yes",$L$2:$L3,"")-1)))
A4: =IF(COUNTA($B4:$E4,$K4)=0,"",IF(AND($B4<>"",$C4<>"",$D4<>"",$E4<>""),"TXS"&TEXT(COUNTIFS($B$2:$B4,"<>",$C$2:$C4,"<>",$D$2:$D4,"<>",$E$2:$E4,"<>"),"00000"),"")) | H4: =IF(NOT(AND($B4<>"",$C4<>"",$D4<>"",$E4<>"")),"",IF($A4="","","CDI plate "&INT((VALUE(RIGHT($A4,5))-1)/96)+1&": "&CHAR(65+INT(MOD(VALUE(RIGHT($A4,5))-1,96)/12))&(MOD(VALUE(RIGHT($A4,5))-1,12)+1))) | I4: =IF(NOT(AND($B4<>"",$C4<>"",$D4<>"",$E4<>"")),"",IF($A4="","","NIH plate "&INT((VALUE(RIGHT($A4,5))-1)/96)+1&": "&CHAR(65+INT(MOD(VALUE(RIGHT($A4,5))-1,96)/12))&(MOD(VALUE(RIGHT($A4,5))-1,12)+1))) | J4: =IF(NOT(AND($B4<>"",$C4<>"",$D4<>"",$E4<>"")),"",IF($A4="","","Max Planck plate "&INT((VALUE(RIGHT($A4,5))-1)/96)+1&": "&CHAR(65+INT(MOD(VALUE(RIGHT($A4,5))-1,96)/12))&(MOD(VALUE(RIGHT($A4,5))-1,12)+1))) | L4: =IF(OR(NOT(AND($B4<>"",$C4<>"",$D4<>"",$E4<>"")),$A4="",$K4<>"Yes"),"",IF($L4<>"",$L4,INDEX(SETUP!$I$1:$I$2000,MATCH(TRUE,SETUP!$J$1:$J$2000,0)+COUNTIFS($A$2:$A4,"<>",$K$2:$K4,"Yes",$L$2:$L4,"")-1)))
A5: =IF(COUNTA($B5:$E5,$K5)=0,"",IF(AND($B5<>"",$C5<>"",$D5<>"",$E5<>""),"TXS"&TEXT(COUNTIFS($B$2:$B5,"<>",$C$2:$C5,"<>",$D$2:$D5,"<>",$E$2:$E5,"<>"),"00000"),"")) | H5: =IF(NOT(AND($B5<>"",$C5<>"",$D5<>"",$E5<>"")),"",IF($A5="","","CDI plate "&INT((VALUE(RIGHT($A5,5))-1)/96)+1&": "&CHAR(65+INT(MOD(VALUE(RIGHT($A5,5))-1,96)/12))&(MOD(VALUE(RIGHT($A5,5))-1,12)+1))) | I5: =IF(NOT(AND($B5<>"",$C5<>"",$D5<>"",$E5<>"")),"",IF($A5="","","NIH plate "&INT((VALUE(RIGHT($A5,5))-1)/96)+1&": "&CHAR(65+INT(MOD(VALUE(RIGHT($A5,5))-1,96)/12))&(MOD(VALUE(RIGHT($A5,5))-1,12)+1))) | J5: =IF(NOT(AND($B5<>"",$C5<>"",$D5<>"",$E5<>"")),"",IF($A5="","","Max Planck plate "&INT((VALUE(RIGHT($A5,5))-1)/96)+1&": "&CHAR(65+INT(MOD(VALUE(RIGHT($A5,5))-1,96)/12))&(MOD(VALUE(RIGHT($A5,5))-1,12)+1))) | L5: =IF(OR(NOT(AND($B5<>"",$C5<>"",$D5<>"",$E5<>"")),$A5="",$K5<>"Yes"),"",IF($L5<>"",$L5,INDEX(SETUP!$I$1:$I$2000,MATCH(TRUE,SETUP!$J$1:$J$2000,0)+COUNTIFS($A$2:$A5,"<>",$K$2:$K5,"Yes",$L$2:$L5,"")-1)))
A6: =IF(COUNTA($B6:$E6,$K6)=0,"",IF(AND($B6<>"",$C6<>"",$D6<>"",$E6<>""),"TXS"&TEXT(COUNTIFS($B$2:$B6,"<>",$C$2:$C6,"<>",$D$2:$D6,"<>",$E$2:$E6,"<>"),"00000"),"")) | H6: =IF(NOT(AND($B6<>"",$C6<>"",$D6<>"",$E6<>"")),"",IF($A6="","","CDI plate "&INT((VALUE(RIGHT($A6,5))-1)/96)+1&": "&CHAR(65+INT(MOD(VALUE(RIGHT($A6,5))-1,96)/12))&(MOD(VALUE(RIGHT($A6,5))-1,12)+1))) | I6: =IF(NOT(AND($B6<>"",$C6<>"",$D6<>"",$E6<>"")),"",IF($A6="","","NIH plate "&INT((VALUE(RIGHT($A6,5))-1)/96)+1&": "&CHAR(65+INT(MOD(VALUE(RIGHT($A6,5))-1,96)/12))&(MOD(VALUE(RIGHT($A6,5))-1,12)+1))) | J6: =IF(NOT(AND($B6<>"",$C6<>"",$D6<>"",$E6<>"")),"",IF($A6="","","Max Planck plate "&INT((VALUE(RIGHT($A6,5))-1)/96)+1&": "&CHAR(65+INT(MOD(VALUE(RIGHT($A6,5))-1,96)/12))&(MOD(VALUE(RIGHT($A6,5))-1,12)+1))) | L6: =IF(OR(NOT(AND($B6<>"",$C6<>"",$D6<>"",$E6<>"")),$A6="",$K6<>"Yes"),"",IF($L6<>"",$L6,INDEX(SETUP!$I$1:$I$2000,MATCH(TRUE,SETUP!$J$1:$J$2000,0)+COUNTIFS($A$2:$A6,"<>",$K$2:$K6,"Yes",$L$2:$L6,"")-1)))
A7: =IF(COUNTA($B7:$E7,$K7)=0,"",IF(AND($B7<>"",$C7<>"",$D7<>"",$E7<>""),"TXS"&TEXT(COUNTIFS($B$2:$B7,"<>",$C$2:$C7,"<>",$D$2:$D7,"<>",$E$2:$E7,"<>"),"00000"),"")) | H7: =IF(NOT(AND($B7<>"",$C7<>"",$D7<>"",$E7<>"")),"",IF($A7="","","CDI plate "&INT((VALUE(RIGHT($A7,5))-1)/96)+1&": "&CHAR(65+INT(MOD(VALUE(RIGHT($A7,5))-1,96)/12))&(MOD(VALUE(RIGHT($A7,5))-1,12)+1))) | I7: =IF(NOT(AND($B7<>"",$C7<>"",$D7<>"",$E7<>"")),"",IF($A7="","","NIH plate "&INT((VALUE(RIGHT($A7,5))-1)/96)+1&": "&CHAR(65+INT(MOD(VALUE(RIGHT($A7,5))-1,96)/12))&(MOD(VALUE(RIGHT($A7,5))-1,12)+1))) | J7: =IF(NOT(AND($B7<>"",$C7<>"",$D7<>"",$E7<>"")),"",IF($A7="","","Max Planck plate "&INT((VALUE(RIGHT($A7,5))-1)/96)+1&": "&CHAR(65+INT(MOD(VALUE(RIGHT($A7,5))-1,96)/12))&(MOD(VALUE(RIGHT($A7,5))-1,12)+1))) | L7: =IF(OR(NOT(AND($B7<>"",$C7<>"",$D7<>"",$E7<>"")),$A7="",$K7<>"Yes"),"",IF($L7<>"",$L7,INDEX(SETUP!$I$1:$I$2000,MATCH(TRUE,SETUP!$J$1:$J$2000,0)+COUNTIFS($A$2:$A7,"<>",$K$2:$K7,"Yes",$L$2:$L7,"")-1)))
A8: =IF(COUNTA($B8:$E8,$K8)=0,"",IF(AND($B8<>"",$C8<>"",$D8<>"",$E8<>""),"TXS"&TEXT(COUNTIFS($B$2:$B8,"<>",$C$2:$C8,"<>",$D$2:$D8,"<>",$E$2:$E8,"<>"),"00000"),"")) | H8: =IF(NOT(AND($B8<>"",$C8<>"",$D8<>"",$E8<>"")),"",IF($A8="","","CDI plate "&INT((VALUE(RIGHT($A8,5))-1)/96)+1&": "&CHAR(65+INT(MOD(VALUE(RIGHT($A8,5))-1,96)/12))&(MOD(VALUE(RIGHT($A8,5))-1,12)+1))) | I8: =IF(NOT(AND($B8<>"",$C8<>"",$D8<>"",$E8<>"")),"",IF($A8="","","NIH plate "&INT((VALUE(RIGHT($A8,5))-1)/96)+1&": "&CHAR(65+INT(MOD(VALUE(RIGHT($A8,5))-1,96)/12))&(MOD(VALUE(RIGHT($A8,5))-1,12)+1))) | J8: =IF(NOT(AND($B8<>"",$C8<>"",$D8<>"",$E8<>"")),"",IF($A8="","","Max Planck plate "&INT((VALUE(RIGHT($A8,5))-1)/96)+1&": "&CHAR(65+INT(MOD(VALUE(RIGHT($A8,5))-1,96)/12))&(MOD(VALUE(RIGHT($A8,5))-1,12)+1))) | L8: =IF(OR(NOT(AND($B8<>"",$C8<>"",$D8<>"",$E8<>"")),$A8="",$K8<>"Yes"),"",IF($L8<>"",$L8,INDEX(SETUP!$I$1:$I$2000,MATCH(TRUE,SETUP!$J$1:$J$2000,0)+COUNTIFS($A$2:$A8,"<>",$K$2:$K8,"Yes",$L$2:$L8,"")-1)))
A9: =IF(COUNTA($B9:$E9,$K9)=0,"",IF(AND($B9<>"",$C9<>"",$D9<>"",$E9<>""),"TXS"&TEXT(COUNTIFS($B$2:$B9,"<>",$C$2:$C9,"<>",$D$2:$D9,"<>",$E$2:$E9,"<>"),"00000"),"")) | H9: =IF(NOT(AND($B9<>"",$C9<>"",$D9<>"",$E9<>"")),"",IF($A9="","","CDI plate "&INT((VALUE(RIGHT($A9,5))-1)/96)+1&": "&CHAR(65+INT(MOD(VALUE(RIGHT($A9,5))-1,96)/12))&(MOD(VALUE(RIGHT($A9,5))-1,12)+1))) | I9: =IF(NOT(AND($B9<>"",$C9<>"",$D9<>"",$E9<>"")),"",IF($A9="","","NIH plate "&INT((VALUE(RIGHT($A9,5))-1)/96)+1&": "&CHAR(65+INT(MOD(VALUE(RIGHT($A9,5))-1,96)/12))&(MOD(VALUE(RIGHT($A9,5))-1,12)+1))) | J9: =IF(NOT(AND($B9<>"",$C9<>"",$D9<>"",$E9<>"")),"",IF($A9="","","Max Planck plate "&INT((VALUE(RIGHT($A9,5))-1)/96)+1&": "&CHAR(65+INT(MOD(VALUE(RIGHT($A9,5))-1,96)/12))&(MOD(VALUE(RIGHT($A9,5))-1,12)+1))) | L9: =IF(OR(NOT(AND($B9<>"",$C9<>"",$D9<>"",$E9<>"")),$A9="",$K9<>"Yes"),"",IF($L9<>"",$L9,INDEX(SETUP!$I$1:$I$2000,MATCH(TRUE,SETUP!$J$1:$J$2000,0)+COUNTIFS($A$2:$A9,"<>",$K$2:$K9,"Yes",$L$2:$L9,"")-1)))
A10: =IF(COUNTA($B10:$E10,$K10)=0,"",IF(AND($B10<>"",$C10<>"",$D10<>"",$E10<>""),"TXS"&TEXT(COUNTIFS($B$2:$B10,"<>",$C$2:$C10,"<>",$D$2:$D10,"<>",$E$2:$E10,"<>"),"00000"),"")) | H10: =IF(NOT(AND($B10<>"",$C10<>"",$D10<>"",$E10<>"")),"",IF($A10="","","CDI plate "&INT((VALUE(RIGHT($A10,5))-1)/96)+1&": "&CHAR(65+INT(MOD(VALUE(RIGHT($A10,5))-1,96)/12))&(MOD(VALUE(RIGHT($A10,5))-1,12)+1))) | I10: =IF(NOT(AND($B10<>"",$C10<>"",$D10<>"",$E10<>"")),"",IF($A10="","","NIH plate "&INT((VALUE(RIGHT($A10,5))-1)/96)+1&": "&CHAR(65+INT(MOD(VALUE(RIGHT($A10,5))-1,96)/12))&(MOD(VALUE(RIGHT($A10,5))-1,12)+1))) | J10: =IF(NOT(AND($B10<>"",$C10<>"",$D10<>"",$E10<>"")),"",IF($A10="","","Max Planck plate "&INT((VALUE(RIGHT($A10,5))-1)/96)+1&": "&CHAR(65+INT(MOD(VALUE(RIGHT($A10,5))-1,96)/12))&(MOD(VALUE(RIGHT($A10,5))-1,12)+1))) | L10: =IF(OR(NOT(AND($B10<>"",$C10<>"",$D10<>"",$E10<>"")),$A10="",$K10<>"Yes"),"",IF($L10<>"",$L10,INDEX(SETUP!$I$1:$I$2000,MATCH(TRUE,SETUP!$J$1:$J$2000,0)+COUNTIFS($A$2:$A10,"<>",$K$2:$K10,"Yes",$L$2:$L10,"")-1)))
A11: =IF(COUNTA($B11:$E11,$K11)=0,"",IF(AND($B11<>"",$C11<>"",$D11<>"",$E11<>""),"TXS"&TEXT(COUNTIFS($B$2:$B11,"<>",$C$2:$C11,"<>",$D$2:$D11,"<>",$E$2:$E11,"<>"),"00000"),"")) | H11: =IF(NOT(AND($B11<>"",$C11<>"",$D11<>"",$E11<>"")),"",IF($A11="","","CDI plate "&INT((VALUE(RIGHT($A11,5))-1)/96)+1&": "&CHAR(65+INT(MOD(VALUE(RIGHT($A11,5))-1,96)/12))&(MOD(VALUE(RIGHT($A11,5))-1,12)+1))) | I11: =IF(NOT(AND($B11<>"",$C11<>"",$D11<>"",$E11<>"")),"",IF($A11="","","NIH plate "&INT((VALUE(RIGHT($A11,5))-1)/96)+1&": "&CHAR(65+INT(MOD(VALUE(RIGHT($A11,5))-1,96)/12))&(MOD(VALUE(RIGHT($A11,5))-1,12)+1))) | J11: =IF(NOT(AND($B11<>"",$C11<>"",$D11<>"",$E11<>"")),"",IF($A11="","","Max Planck plate "&INT((VALUE(RIGHT($A11,5))-1)/96)+1&": "&CHAR(65+INT(MOD(VALUE(RIGHT($A11,5))-1,96)/12))&(MOD(VALUE(RIGHT($A11,5))-1,12)+1))) | L11: =IF(OR(NOT(AND($B11<>"",$C11<>"",$D11<>"",$E11<>"")),$A11="",$K11<>"Yes"),"",IF($L11<>"",$L11,INDEX(SETUP!$I$1:$I$2000,MATCH(TRUE,SETUP!$J$1:$J$2000,0)+COUNTIFS($A$2:$A11,"<>",$K$2:$K11,"Yes",$L$2:$L11,"")-1)))
A12: =IF(COUNTA($B12:$E12,$K12)=0,"",IF(AND($B12<>"",$C12<>"",$D12<>"",$E12<>""),"TXS"&TEXT(COUNTIFS($B$2:$B12,"<>",$C$2:$C12,"<>",$D$2:$D12,"<>",$E$2:$E12,"<>"),"00000"),"")) | H12: =IF(NOT(AND($B12<>"",$C12<>"",$D12<>"",$E12<>"")),"",IF($A12="","","CDI plate "&INT((VALUE(RIGHT($A12,5))-1)/96)+1&": "&CHAR(65+INT(MOD(VALUE(RIGHT($A12,5))-1,96)/12))&(MOD(VALUE(RIGHT($A12,5))-1,12)+1))) | I12: =IF(NOT(AND($B12<>"",$C12<>"",$D12<>"",$E12<>"")),"",IF($A12="","","NIH plate "&INT((VALUE(RIGHT($A12,5))-1)/96)+1&": "&CHAR(65+INT(MOD(VALUE(RIGHT($A12,5))-1,96)/12))&(MOD(VALUE(RIGHT($A12,5))-1,12)+1))) | J12: =IF(NOT(AND($B12<>"",$C12<>"",$D12<>"",$E12<>"")),"",IF($A12="","","Max Planck plate "&INT((VALUE(RIGHT($A12,5))-1)/96)+1&": "&CHAR(65+INT(MOD(VALUE(RIGHT($A12,5))-1,96)/12))&(MOD(VALUE(RIGHT($A12,5))-1,12)+1))) | L12: =IF(OR(NOT(AND($B12<>"",$C12<>"",$D12<>"",$E12<>"")),$A12="",$K12<>"Yes"),"",IF($L12<>"",$L12,INDEX(SETUP!$I$1:$I$2000,MATCH(TRUE,SETUP!$J$1:$J$2000,0)+COUNTIFS($A$2:$A12,"<>",$K$2:$K12,"Yes",$L$2:$L12,"")-1)))
A13: =IF(COUNTA($B13:$E13,$K13)=0,"",IF(AND($B13<>"",$C13<>"",$D13<>"",$E13<>""),"TXS"&TEXT(COUNTIFS($B$2:$B13,"<>",$C$2:$C13,"<>",$D$2:$D13,"<>",$E$2:$E13,"<>"),"00000"),"")) | H13: =IF(NOT(AND($B13<>"",$C13<>"",$D13<>"",$E13<>"")),"",IF($A13="","","CDI plate "&INT((VALUE(RIGHT($A13,5))-1)/96)+1&": "&CHAR(65+INT(MOD(VALUE(RIGHT($A13,5))-1,96)/12))&(MOD(VALUE(RIGHT($A13,5))-1,12)+1))) | I13: =IF(NOT(AND($B13<>"",$C13<>"",$D13<>"",$E13<>"")),"",IF($A13="","","NIH plate "&INT((VALUE(RIGHT($A13,5))-1)/96)+1&": "&CHAR(65+INT(MOD(VALUE(RIGHT($A13,5))-1,96)/12))&(MOD(VALUE(RIGHT($A13,5))-1,12)+1))) | J13: =IF(NOT(AND($B13<>"",$C13<>"",$D13<>"",$E13<>"")),"",IF($A13="","","Max Planck plate "&INT((VALUE(RIGHT($A13,5))-1)/96)+1&": "&CHAR(65+INT(MOD(VALUE(RIGHT($A13,5))-1,96)/12))&(MOD(VALUE(RIGHT($A13,5))-1,12)+1))) | L13: =IF(OR(NOT(AND($B13<>"",$C13<>"",$D13<>"",$E13<>"")),$A13="",$K13<>"Yes"),"",IF($L13<>"",$L13,INDEX(SETUP!$I$1:$I$2000,MATCH(TRUE,SETUP!$J$1:$J$2000,0)+COUNTIFS($A$2:$A13,"<>",$K$2:$K13,"Yes",$L$2:$L13,"")-1)))
... A45: =IF(COUNTA($B45:$E45,$K45)=0,"",IF(AND($B45<>"",$C45<>"",$D45<>"",$E45<>""),"TXS"&TEXT(COUNTIFS($B$2:$B45,"<>",$C$2:$C45,"<>",$D$2:$D45,"<>",$E$2:$E45,"<>"),"00000"),"")) | H45: =IF(NOT(AND($B45<>"",$C45<>"",$D45<>"",$E45<>"")),"",IF($A45="","","CDI plate "&INT((VALUE(RIGHT($A45,5))-1)/96)+1&": "&CHAR(65+INT(MOD(VALUE(RIGHT($A45,5))-1,96)/12))&(MOD(VALUE(RIGHT($A45,5))-1,12)+1))) | I45: =IF(NOT(AND($B45<>"",$C45<>"",$D45<>"",$E45<>"")),"",IF($A45="","","NIH plate "&INT((VALUE(RIGHT($A45,5))-1)/96)+1&": "&CHAR(65+INT(MOD(VALUE(RIGHT($A45,5))-1,96)/12))&(MOD(VALUE(RIGHT($A45,5))-1,12)+1))) | J45: =IF(NOT(AND($B45<>"",$C45<>"",$D45<>"",$E45<>"")),"",IF($A45="","","Max Planck plate "&INT((VALUE(RIGHT($A45,5))-1)/96)+1&": "&CHAR(65+INT(MOD(VALUE(RIGHT($A45,5))-1,96)/12))&(MOD(VALUE(RIGHT($A45,5))-1,12)+1))) | L45: =IF(OR(NOT(AND($B45<>"",$C45<>"",$D45<>"",$E45<>"")),$A45="",$K45<>"Yes"),"",IF($L45<>"",$L45,INDEX(SETUP!$I$1:$I$2000,MATCH(TRUE,SETUP!$J$1:$J$2000,0)+COUNTIFS($A$2:$A45,"<>",$K$2:$K45,"Yes",$L$2:$L45,"")-1)))
A46: =IF(COUNTA($B46:$E46,$K46)=0,"",IF(AND($B46<>"",$C46<>"",$D46<>"",$E46<>""),"TXS"&TEXT(COUNTIFS($B$2:$B46,"<>",$C$2:$C46,"<>",$D$2:$D46,"<>",$E$2:$E46,"<>"),"00000"),"")) | I46: =IF(NOT(AND($B46<>"",$C46<>"",$D46<>"",$E46<>"")),"",IF($A46="","","NIH plate "&INT((VALUE(RIGHT($A46,5))-1)/96)+1&": "&CHAR(65+INT(MOD(VALUE(RIGHT($A46,5))-1,96)/12))&(MOD(VALUE(RIGHT($A46,5))-1,12)+1))) | J46: =IF(NOT(AND($B46<>"",$C46<>"",$D46<>"",$E46<>"")),"",IF($A46="","","Max Planck plate "&INT((VALUE(RIGHT($A46,5))-1)/96)+1&": "&CHAR(65+INT(MOD(VALUE(RIGHT($A46,5))-1,96)/12))&(MOD(VALUE(RIGHT($A46,5))-1,12)+1))) | L46: =IF(OR(NOT(AND($B46<>"",$C46<>"",$D46<>"",$E46<>"")),$A46="",$K46<>"Yes"),"",IF($L46<>"",$L46,INDEX(SETUP!$I$1:$I$2000,MATCH(TRUE,SETUP!$J$1:$J$2000,0)+COUNTIFS($A$2:$A46,"<>",$K$2:$K46,"Yes",$L$2:$L46,"")-1)))
A47: =IF(COUNTA($B47:$E47,$K47)=0,"",IF(AND($B47<>"",$C47<>"",$D47<>"",$E47<>""),"TXS"&TEXT(COUNTIFS($B$2:$B47,"<>",$C$2:$C47,"<>",$D$2:$D47,"<>",$E$2:$E47,"<>"),"00000"),"")) | H47: =IF(NOT(AND($B47<>"",$C47<>"",$D47<>"",$E47<>"")),"",IF($A47="","","CDI plate "&INT((VALUE(RIGHT($A47,5))-1)/96)+1&": "&CHAR(65+INT(MOD(VALUE(RIGHT($A47,5))-1,96)/12))&(MOD(VALUE(RIGHT($A47,5))-1,12)+1))) | I47: =IF(NOT(AND($B47<>"",$C47<>"",$D47<>"",$E47<>"")),"",IF($A47="","","NIH plate "&INT((VALUE(RIGHT($A47,5))-1)/96)+1&": "&CHAR(65+INT(MOD(VALUE(RIGHT($A47,5))-1,96)/12))&(MOD(VALUE(RIGHT($A47,5))-1,12)+1))) | J47: =IF(NOT(AND($B47<>"",$C47<>"",$D47<>"",$E47<>"")),"",IF($A47="","","Max Planck plate "&INT((VALUE(RIGHT($A47,5))-1)/96)+1&": "&CHAR(65+INT(MOD(VALUE(RIGHT($A47,5))-1,96)/12))&(MOD(VALUE(RIGHT($A47,5))-1,12)+1))) | L47: =IF(OR(NOT(AND($B47<>"",$C47<>"",$D47<>"",$E47<>"")),$A47="",$K47<>"Yes"),"",IF($L47<>"",$L47,INDEX(SETUP!$I$1:$I$2000,MATCH(TRUE,SETUP!$J$1:$J$2000,0)+COUNTIFS($A$2:$A47,"<>",$K$2:$K47,"Yes",$L$2:$L47,"")-1)))
A48: =IF(COUNTA($B48:$E48,$K48)=0,"",IF(AND($B48<>"",$C48<>"",$D48<>"",$E48<>""),"TXS"&TEXT(COUNTIFS($B$2:$B48,"<>",$C$2:$C48,"<>",$D$2:$D48,"<>",$E$2:$E48,"<>"),"00000"),"")) | H48: =IF(NOT(AND($B48<>"",$C48<>"",$D48<>"",$E48<>"")),"",IF($A48="","","CDI plate "&INT((VALUE(RIGHT($A48,5))-1)/96)+1&": "&CHAR(65+INT(MOD(VALUE(RIGHT($A48,5))-1,96)/12))&(MOD(VALUE(RIGHT($A48,5))-1,12)+1))) | I48: =IF(NOT(AND($B48<>"",$C48<>"",$D48<>"",$E48<>"")),"",IF($A48="","","NIH plate "&INT((VALUE(RIGHT($A48,5))-1)/96)+1&": "&CHAR(65+INT(MOD(VALUE(RIGHT($A48,5))-1,96)/12))&(MOD(VALUE(RIGHT($A48,5))-1,12)+1))) | J48: =IF(NOT(AND($B48<>"",$C48<>"",$D48<>"",$E48<>"")),"",IF($A48="","","Max Planck plate "&INT((VALUE(RIGHT($A48,5))-1)/96)+1&": "&CHAR(65+INT(MOD(VALUE(RIGHT($A48,5))-1,96)/12))&(MOD(VALUE(RIGHT($A48,5))-1,12)+1))) | L48: =IF(OR(NOT(AND($B48<>"",$C48<>"",$D48<>"",$E48<>"")),$A48="",$K48<>"Yes"),"",IF($L48<>"",$L48,INDEX(SETUP!$I$1:$I$2000,MATCH(TRUE,SETUP!$J$1:$J$2000,0)+COUNTIFS($A$2:$A48,"<>",$K$2:$K48,"Yes",$L$2:$L48,"")-1)))
A49: =IF(COUNTA($B49:$E49,$K49)=0,"",IF(AND($B49<>"",$C49<>"",$D49<>"",$E49<>""),"TXS"&TEXT(COUNTIFS($B$2:$B49,"<>",$C$2:$C49,"<>",$D$2:$D49,"<>",$E$2:$E49,"<>"),"00000"),"")) | H49: =IF(NOT(AND($B49<>"",$C49<>"",$D49<>"",$E49<>"")),"",IF($A49="","","CDI plate "&INT((VALUE(RIGHT($A49,5))-1)/96)+1&": "&CHAR(65+INT(MOD(VALUE(RIGHT($A49,5))-1,96)/12))&(MOD(VALUE(RIGHT($A49,5))-1,12)+1))) | I49: =IF(NOT(AND($B49<>"",$C49<>"",$D49<>"",$E49<>"")),"",IF($A49="","","NIH plate "&INT((VALUE(RIGHT($A49,5))-1)/96)+1&": "&CHAR(65+INT(MOD(VALUE(RIGHT($A49,5))-1,96)/12))&(MOD(VALUE(RIGHT($A49,5))-1,12)+1))) | J49: =IF(NOT(AND($B49<>"",$C49<>"",$D49<>"",$E49<>"")),"",IF($A49="","","Max Planck plate "&INT((VALUE(RIGHT($A49,5))-1)/96)+1&": "&CHAR(65+INT(MOD(VALUE(RIGHT($A49,5))-1,96)/12))&(MOD(VALUE(RIGHT($A49,5))-1,12)+1))) | L49: =IF(OR(NOT(AND($B49<>"",$C49<>"",$D49<>"",$E49<>"")),$A49="",$K49<>"Yes"),"",IF($L49<>"",$L49,INDEX(SETUP!$I$1:$I$2000,MATCH(TRUE,SETUP!$J$1:$J$2000,0)+COUNTIFS($A$2:$A49,"<>",$K$2:$K49,"Yes",$L$2:$L49,"")-1)))
A50: =IF(COUNTA($B50:$E50,$K50)=0,"",IF(AND($B50<>"",$C50<>"",$D50<>"",$E50<>""),"TXS"&TEXT(COUNTIFS($B$2:$B50,"<>",$C$2:$C50,"<>",$D$2:$D50,"<>",$E$2:$E50,"<>"),"00000"),"")) | H50: =IF(NOT(AND($B50<>"",$C50<>"",$D50<>"",$E50<>"")),"",IF($A50="","","CDI plate "&INT((VALUE(RIGHT($A50,5))-1)/96)+1&": "&CHAR(65+INT(MOD(VALUE(RIGHT($A50,5))-1,96)/12))&(MOD(VALUE(RIGHT($A50,5))-1,12)+1))) | I50: =IF(NOT(AND($B50<>"",$C50<>"",$D50<>"",$E50<>"")),"",IF($A50="","","NIH plate "&INT((VALUE(RIGHT($A50,5))-1)/96)+1&": "&CHAR(65+INT(MOD(VALUE(RIGHT($A50,5))-1,96)/12))&(MOD(VALUE(RIGHT($A50,5))-1,12)+1))) | J50: =IF(NOT(AND($B50<>"",$C50<>"",$D50<>"",$E50<>"")),"",IF($A50="","","Max Planck plate "&INT((VALUE(RIGHT($A50,5))-1)/96)+1&": "&CHAR(65+INT(MOD(VALUE(RIGHT($A50,5))-1,96)/12))&(MOD(VALUE(RIGHT($A50,5))-1,12)+1))) | L50: =IF(OR(NOT(AND($B50<>"",$C50<>"",$D50<>"",$E50<>"")),$A50="",$K50<>"Yes"),"",IF($L50<>"",$L50,INDEX(SETUP!$I$1:$I$2000,MATCH(TRUE,SETUP!$J$1:$J$2000,0)+COUNTIFS($A$2:$A50,"<>",$K$2:$K50,"Yes",$L$2:$L50,"")-1)))
A51: =IF(COUNTA($B51:$E51,$K51)=0,"",IF(AND($B51<>"",$C51<>"",$D51<>"",$E51<>""),"TXS"&TEXT(COUNTIFS($B$2:$B51,"<>",$C$2:$C51,"<>",$D$2:$D51,"<>",$E$2:$E51,"<>"),"00000"),"")) | H51: =IF(NOT(AND($B51<>"",$C51<>"",$D51<>"",$E51<>"")),"",IF($A51="","","CDI plate "&INT((VALUE(RIGHT($A51,5))-1)/96)+1&": "&CHAR(65+INT(MOD(VALUE(RIGHT($A51,5))-1,96)/12))&(MOD(VALUE(RIGHT($A51,5))-1,12)+1))) | J51: =IF(NOT(AND($B51<>"",$C51<>"",$D51<>"",$E51<>"")),"",IF($A51="","","Max Planck plate "&INT((VALUE(RIGHT($A51,5))-1)/96)+1&": "&CHAR(65+INT(MOD(VALUE(RIGHT($A51,5))-1,96)/12))&(MOD(VALUE(RIGHT($A51,5))-1,12)+1))) | L51: =IF(OR(NOT(AND($B51<>"",$C51<>"",$D51<>"",$E51<>"")),$A51="",$K51<>"Yes"),"",IF($L51<>"",$L51,INDEX(SETUP!$I$1:$I$2000,MATCH(TRUE,SETUP!$J$1:$J$2000,0)+COUNTIFS($A$2:$A51,"<>",$K$2:$K51,"Yes",$L$2:$L51,"")-1)))
A52: =IF(COUNTA($B52:$E52,$K52)=0,"",IF(AND($B52<>"",$C52<>"",$D52<>"",$E52<>""),"TXS"&TEXT(COUNTIFS($B$2:$B52,"<>",$C$2:$C52,"<>",$D$2:$D52,"<>",$E$2:$E52,"<>"),"00000"),"")) | H52: =IF(NOT(AND($B52<>"",$C52<>"",$D52<>"",$E52<>"")),"",IF($A52="","","CDI plate "&INT((VALUE(RIGHT($A52,5))-1)/96)+1&": "&CHAR(65+INT(MOD(VALUE(RIGHT($A52,5))-1,96)/12))&(MOD(VALUE(RIGHT($A52,5))-1,12)+1))) | I52: =IF(NOT(AND($B52<>"",$C52<>"",$D52<>"",$E52<>"")),"",IF($A52="","","NIH plate "&INT((VALUE(RIGHT($A52,5))-1)/96)+1&": "&CHAR(65+INT(MOD(VALUE(RIGHT($A52,5))-1,96)/12))&(MOD(VALUE(RIGHT($A52,5))-1,12)+1))) | J52: =IF(NOT(AND($B52<>"",$C52<>"",$D52<>"",$E52<>"")),"",IF($A52="","","Max Planck plate "&INT((VALUE(RIGHT($A52,5))-1)/96)+1&": "&CHAR(65+INT(MOD(VALUE(RIGHT($A52,5))-1,96)/12))&(MOD(VALUE(RIGHT($A52,5))-1,12)+1))) | L52: =IF(OR(NOT(AND($B52<>"",$C52<>"",$D52<>"",$E52<>"")),$A52="",$K52<>"Yes"),"",IF($L52<>"",$L52,INDEX(SETUP!$I$1:$I$2000,MATCH(TRUE,SETUP!$J$1:$J$2000,0)+COUNTIFS($A$2:$A52,"<>",$K$2:$K52,"Yes",$L$2:$L52,"")-1)))
A53: =IF(COUNTA($B53:$E53,$K53)=0,"",IF(AND($B53<>"",$C53<>"",$D53<>"",$E53<>""),"TXS"&TEXT(COUNTIFS($B$2:$B53,"<>",$C$2:$C53,"<>",$D$2:$D53,"<>",$E$2:$E53,"<>"),"00000"),"")) | H53: =IF(NOT(AND($B53<>"",$C53<>"",$D53<>"",$E53<>"")),"",IF($A53="","","CDI plate "&INT((VALUE(RIGHT($A53,5))-1)/96)+1&": "&CHAR(65+INT(MOD(VALUE(RIGHT($A53,5))-1,96)/12))&(MOD(VALUE(RIGHT($A53,5))-1,12)+1))) | I53: =IF(NOT(AND($B53<>"",$C53<>"",$D53<>"",$E53<>"")),"",IF($A53="","","NIH plate "&INT((VALUE(RIGHT($A53,5))-1)/96)+1&": "&CHAR(65+INT(MOD(VALUE(RIGHT($A53,5))-1,96)/12))&(MOD(VALUE(RIGHT($A53,5))-1,12)+1))) | J53: =IF(NOT(AND($B53<>"",$C53<>"",$D53<>"",$E53<>"")),"",IF($A53="","","Max Planck plate "&INT((VALUE(RIGHT($A53,5))-1)/96)+1&": "&CHAR(65+INT(MOD(VALUE(RIGHT($A53,5))-1,96)/12))&(MOD(VALUE(RIGHT($A53,5))-1,12)+1))) | L53: =IF(OR(NOT(AND($B53<>"",$C53<>"",$D53<>"",$E53<>"")),$A53="",$K53<>"Yes"),"",IF($L53<>"",$L53,INDEX(SETUP!$I$1:$I$2000,MATCH(TRUE,SETUP!$J$1:$J$2000,0)+COUNTIFS($A$2:$A53,"<>",$K$2:$K53,"Yes",$L$2:$L53,"")-1)))
A54: =IF(COUNTA($B54:$E54,$K54)=0,"",IF(AND($B54<>"",$C54<>"",$D54<>"",$E54<>""),"TXS"&TEXT(COUNTIFS($B$2:$B54,"<>",$C$2:$C54,"<>",$D$2:$D54,"<>",$E$2:$E54,"<>"),"00000"),"")) | H54: =IF(NOT(AND($B54<>"",$C54<>"",$D54<>"",$E54<>"")),"",IF($A54="","","CDI plate "&INT((VALUE(RIGHT($A54,5))-1)/96)+1&": "&CHAR(65+INT(MOD(VALUE(RIGHT($A54,5))-1,96)/12))&(MOD(VALUE(RIGHT($A54,5))-1,12)+1))) | I54: =IF(NOT(AND($B54<>"",$C54<>"",$D54<>"",$E54<>"")),"",IF($A54="","","NIH plate "&INT((VALUE(RIGHT($A54,5))-1)/96)+1&": "&CHAR(65+INT(MOD(VALUE(RIGHT($A54,5))-1,96)/12))&(MOD(VALUE(RIGHT($A54,5))-1,12)+1))) | J54: =IF(NOT(AND($B54<>"",$C54<>"",$D54<>"",$E54<>"")),"",IF($A54="","","Max Planck plate "&INT((VALUE(RIGHT($A54,5))-1)/96)+1&": "&CHAR(65+INT(MOD(VALUE(RIGHT($A54,5))-1,96)/12))&(MOD(VALUE(RIGHT($A54,5))-1,12)+1))) | L54: =IF(OR(NOT(AND($B54<>"",$C54<>"",$D54<>"",$E54<>"")),$A54="",$K54<>"Yes"),"",IF($L54<>"",$L54,INDEX(SETUP!$I$1:$I$2000,MATCH(TRUE,SETUP!$J$1:$J$2000,0)+COUNTIFS($A$2:$A54,"<>",$K$2:$K54,"Yes",$L$2:$L54,"")-1)))
A55: =IF(COUNTA($B55:$E55,$K55)=0,"",IF(AND($B55<>"",$C55<>"",$D55<>"",$E55<>""),"TXS"&TEXT(COUNTIFS($B$2:$B55,"<>",$C$2:$C55,"<>",$D$2:$D55,"<>",$E$2:$E55,"<>"),"00000"),"")) | H55: =IF(NOT(AND($B55<>"",$C55<>"",$D55<>"",$E55<>"")),"",IF($A55="","","CDI plate "&INT((VALUE(RIGHT($A55,5))-1)/96)+1&": "&CHAR(65+INT(MOD(VALUE(RIGHT($A55,5))-1,96)/12))&(MOD(VALUE(RIGHT($A55,5))-1,12)+1))) | I55: =IF(NOT(AND($B55<>"",$C55<>"",$D55<>"",$E55<>"")),"",IF($A55="","","NIH plate "&INT((VALUE(RIGHT($A55,5))-1)/96)+1&": "&CHAR(65+INT(MOD(VALUE(RIGHT($A55,5))-1,96)/12))&(MOD(VALUE(RIGHT($A55,5))-1,12)+1))) | J55: =IF(NOT(AND($B55<>"",$C55<>"",$D55<>"",$E55<>"")),"",IF($A55="","","Max Planck plate "&INT((VALUE(RIGHT($A55,5))-1)/96)+1&": "&CHAR(65+INT(MOD(VALUE(RIGHT($A55,5))-1,96)/12))&(MOD(VALUE(RIGHT($A55,5))-1,12)+1))) | L55: =IF(OR(NOT(AND($B55<>"",$C55<>"",$D55<>"",$E55<>"")),$A55="",$K55<>"Yes"),"",IF($L55<>"",$L55,INDEX(SETUP!$I$1:$I$2000,MATCH(TRUE,SETUP!$J$1:$J$2000,0)+COUNTIFS($A$2:$A55,"<>",$K$2:$K55,"Yes",$L$2:$L55,"")-1)))
A56: =IF(COUNTA($B56:$E56,$K56)=0,"",IF(AND($B56<>"",$C56<>"",$D56<>"",$E56<>""),"TXS"&TEXT(COUNTIFS($B$2:$B56,"<>",$C$2:$C56,"<>",$D$2:$D56,"<>",$E$2:$E56,"<>"),"00000"),"")) | H56: =IF(NOT(AND($B56<>"",$C56<>"",$D56<>"",$E56<>"")),"",IF($A56="","","CDI plate "&INT((VALUE(RIGHT($A56,5))-1)/96)+1&": "&CHAR(65+INT(MOD(VALUE(RIGHT($A56,5))-1,96)/12))&(MOD(VALUE(RIGHT($A56,5))-1,12)+1))) | I56: =IF(NOT(AND($B56<>"",$C56<>"",$D56<>"",$E56<>"")),"",IF($A56="","","NIH plate "&INT((VALUE(RIGHT($A56,5))-1)/96)+1&": "&CHAR(65+INT(MOD(VALUE(RIGHT($A56,5))-1,96)/12))&(MOD(VALUE(RIGHT($A56,5))-1,12)+1))) | J56: =IF(NOT(AND($B56<>"",$C56<>"",$D56<>"",$E56<>"")),"",IF($A56="","","Max Planck plate "&INT((VALUE(RIGHT($A56,5))-1)/96)+1&": "&CHAR(65+INT(MOD(VALUE(RIGHT($A56,5))-1,96)/12))&(MOD(VALUE(RIGHT($A56,5))-1,12)+1))) | L56: =IF(OR(NOT(AND($B56<>"",$C56<>"",$D56<>"",$E56<>"")),$A56="",$K56<>"Yes"),"",IF($L56<>"",$L56,INDEX(SETUP!$I$1:$I$2000,MATCH(TRUE,SETUP!$J$1:$J$2000,0)+COUNTIFS($A$2:$A56,"<>",$K$2:$K56,"Yes",$L$2:$L56,"")-1)))
A57: =IF(COUNTA($B57:$E57,$K57)=0,"",IF(AND($B57<>"",$C57<>"",$D57<>"",$E57<>""),"TXS"&TEXT(COUNTIFS($B$2:$B57,"<>",$C$2:$C57,"<>",$D$2:$D57,"<>",$E$2:$E57,"<>"),"00000"),"")) | H57: =IF(NOT(AND($B57<>"",$C57<>"",$D57<>"",$E57<>"")),"",IF($A57="","","CDI plate "&INT((VALUE(RIGHT($A57,5))-1)/96)+1&": "&CHAR(65+INT(MOD(VALUE(RIGHT($A57,5))-1,96)/12))&(MOD(VALUE(RIGHT($A57,5))-1,12)+1))) | I57: =IF(NOT(AND($B57<>"",$C57<>"",$D57<>"",$E57<>"")),"",IF($A57="","","NIH plate "&INT((VALUE(RIGHT($A57,5))-1)/96)+1&": "&CHAR(65+INT(MOD(VALUE(RIGHT($A57,5))-1,96)/12))&(MOD(VALUE(RIGHT($A57,5))-1,12)+1))) | J57: =IF(NOT(AND($B57<>"",$C57<>"",$D57<>"",$E57<>"")),"",IF($A57="","","Max Planck plate "&INT((VALUE(RIGHT($A57,5))-1)/96)+1&": "&CHAR(65+INT(MOD(VALUE(RIGHT($A57,5))-1,96)/12))&(MOD(VALUE(RIGHT($A57,5))-1,12)+1))) | L57: =IF(OR(NOT(AND($B57<>"",$C57<>"",$D57<>"",$E57<>"")),$A57="",$K57<>"Yes"),"",IF($L57<>"",$L57,INDEX(SETUP!$I$1:$I$2000,MATCH(TRUE,SETUP!$J$1:$J$2000,0)+COUNTIFS($A$2:$A57,"<>",$K$2:$K57,"Yes",$L$2:$L57,"")-1)))
A58: =IF(COUNTA($B58:$E58,$K58)=0,"",IF(AND($B58<>"",$C58<>"",$D58<>"",$E58<>""),"TXS"&TEXT(COUNTIFS($B$2:$B58,"<>",$C$2:$C58,"<>",$D$2:$D58,"<>",$E$2:$E58,"<>"),"00000"),"")) | H58: =IF(NOT(AND($B58<>"",$C58<>"",$D58<>"",$E58<>"")),"",IF($A58="","","CDI plate "&INT((VALUE(RIGHT($A58,5))-1)/96)+1&": "&CHAR(65+INT(MOD(VALUE(RIGHT($A58,5))-1,96)/12))&(MOD(VALUE(RIGHT($A58,5))-1,12)+1))) | I58: =IF(NOT(AND($B58<>"",$C58<>"",$D58<>"",$E58<>"")),"",IF($A58="","","NIH plate "&INT((VALUE(RIGHT($A58,5))-1)/96)+1&": "&CHAR(65+INT(MOD(VALUE(RIGHT($A58,5))-1,96)/12))&(MOD(VALUE(RIGHT($A58,5))-1,12)+1))) | J58: =IF(NOT(AND($B58<>"",$C58<>"",$D58<>"",$E58<>"")),"",IF($A58="","","Max Planck plate "&INT((VALUE(RIGHT($A58,5))-1)/96)+1&": "&CHAR(65+INT(MOD(VALUE(RIGHT($A58,5))-1,96)/12))&(MOD(VALUE(RIGHT($A58,5))-1,12)+1))) | L58: =IF(OR(NOT(AND($B58<>"",$C58<>"",$D58<>"",$E58<>"")),$A58="",$K58<>"Yes"),"",IF($L58<>"",$L58,INDEX(SETUP!$I$1:$I$2000,MATCH(TRUE,SETUP!$J$1:$J$2000,0)+COUNTIFS($A$2:$A58,"<>",$K$2:$K58,"Yes",$L$2:$L58,"")-1)))
A59: =IF(COUNTA($B59:$E59,$K59)=0,"",IF(AND($B59<>"",$C59<>"",$D59<>"",$E59<>""),"TXS"&TEXT(COUNTIFS($B$2:$B59,"<>",$C$2:$C59,"<>",$D$2:$D59,"<>",$E$2:$E59,"<>"),"00000"),"")) | H59: =IF(NOT(AND($B59<>"",$C59<>"",$D59<>"",$E59<>"")),"",IF($A59="","","CDI plate "&INT((VALUE(RIGHT($A59,5))-1)/96)+1&": "&CHAR(65+INT(MOD(VALUE(RIGHT($A59,5))-1,96)/12))&(MOD(VALUE(RIGHT($A59,5))-1,12)+1))) | I59: =IF(NOT(AND($B59<>"",$C59<>"",$D59<>"",$E59<>"")),"",IF($A59="","","NIH plate "&INT((VALUE(RIGHT($A59,5))-1)/96)+1&": "&CHAR(65+INT(MOD(VALUE(RIGHT($A59,5))-1,96)/12))&(MOD(VALUE(RIGHT($A59,5))-1,12)+1))) | J59: =IF(NOT(AND($B59<>"",$C59<>"",$D59<>"",$E59<>"")),"",IF($A59="","","Max Planck plate "&INT((VALUE(RIGHT($A59,5))-1)/96)+1&": "&CHAR(65+INT(MOD(VALUE(RIGHT($A59,5))-1,96)/12))&(MOD(VALUE(RIGHT($A59,5))-1,12)+1))) | L59: =IF(OR(NOT(AND($B59<>"",$C59<>"",$D59<>"",$E59<>"")),$A59="",$K59<>"Yes"),"",IF($L59<>"",$L59,INDEX(SETUP!$I$1:$I$2000,MATCH(TRUE,SETUP!$J$1:$J$2000,0)+COUNTIFS($A$2:$A59,"<>",$K$2:$K59,"Yes",$L$2:$L59,"")-1)))
A60: =IF(COUNTA($B60:$E60,$K60)=0,"",IF(AND($B60<>"",$C60<>"",$D60<>"",$E60<>""),"TXS"&TEXT(COUNTIFS($B$2:$B60,"<>",$C$2:$C60,"<>",$D$2:$D60,"<>",$E$2:$E60,"<>"),"00000"),"")) | H60: =IF(NOT(AND($B60<>"",$C60<>"",$D60<>"",$E60<>"")),"",IF($A60="","","CDI plate "&INT((VALUE(RIGHT($A60,5))-1)/96)+1&": "&CHAR(65+INT(MOD(VALUE(RIGHT($A60,5))-1,96)/12))&(MOD(VALUE(RIGHT($A60,5))-1,12)+1))) | I60: =IF(NOT(AND($B60<>"",$C60<>"",$D60<>"",$E60<>"")),"",IF($A60="","","NIH plate "&INT((VALUE(RIGHT($A60,5))-1)/96)+1&": "&CHAR(65+INT(MOD(VALUE(RIGHT($A60,5))-1,96)/12))&(MOD(VALUE(RIGHT($A60,5))-1,12)+1))) | J60: =IF(NOT(AND($B60<>"",$C60<>"",$D60<>"",$E60<>"")),"",IF($A60="","","Max Planck plate "&INT((VALUE(RIGHT($A60,5))-1)/96)+1&": "&CHAR(65+INT(MOD(VALUE(RIGHT($A60,5))-1,96)/12))&(MOD(VALUE(RIGHT($A60,5))-1,12)+1))) | L60: =IF(OR(NOT(AND($B60<>"",$C60<>"",$D60<>"",$E60<>"")),$A60="",$K60<>"Yes"),"",IF($L60<>"",$L60,INDEX(SETUP!$I$1:$I$2000,MATCH(TRUE,SETUP!$J$1:$J$2000,0)+COUNTIFS($A$2:$A60,"<>",$K$2:$K60,"Yes",$L$2:$L60,"")-1)))
A61: =IF(COUNTA($B61:$E61,$K61)=0,"",IF(AND($B61<>"",$C61<>"",$D61<>"",$E61<>""),"TXS"&TEXT(COUNTIFS($B$2:$B61,"<>",$C$2:$C61,"<>",$D$2:$D61,"<>",$E$2:$E61,"<>"),"00000"),"")) | H61: =IF(NOT(AND($B61<>"",$C61<>"",$D61<>"",$E61<>"")),"",IF($A61="","","CDI plate "&INT((VALUE(RIGHT($A61,5))-1)/96)+1&": "&CHAR(65+INT(MOD(VALUE(RIGHT($A61,5))-1,96)/12))&(MOD(VALUE(RIGHT($A61,5))-1,12)+1))) | I61: =IF(NOT(AND($B61<>"",$C61<>"",$D61<>"",$E61<>"")),"",IF($A61="","","NIH plate "&INT((VALUE(RIGHT($A61,5))-1)/96)+1&": "&CHAR(65+INT(MOD(VALUE(RIGHT($A61,5))-1,96)/12))&(MOD(VALUE(RIGHT($A61,5))-1,12)+1))) | J61: =IF(NOT(AND($B61<>"",$C61<>"",$D61<>"",$E61<>"")),"",IF($A61="","","Max Planck plate "&INT((VALUE(RIGHT($A61,5))-1)/96)+1&": "&CHAR(65+INT(MOD(VALUE(RIGHT($A61,5))-1,96)/12))&(MOD(VALUE(RIGHT($A61,5))-1,12)+1))) | L61: =IF(OR(NOT(AND($B61<>"",$C61<>"",$D61<>"",$E61<>"")),$A61="",$K61<>"Yes"),"",IF($L61<>"",$L61,INDEX(SETUP!$I$1:$I$2000,MATCH(TRUE,SETUP!$J$1:$J$2000,0)+COUNTIFS($A$2:$A61,"<>",$K$2:$K61,"Yes",$L$2:$L61,"")-1)))
A62: =IF(COUNTA($B62:$E62,$K62)=0,"",IF(AND($B62<>"",$C62<>"",$D62<>"",$E62<>""),"TXS"&TEXT(COUNTIFS($B$2:$B62,"<>",$C$2:$C62,"<>",$D$2:$D62,"<>",$E$2:$E62,"<>"),"00000"),"")) | H62: =IF(NOT(AND($B62<>"",$C62<>"",$D62<>"",$E62<>"")),"",IF($A62="","","CDI plate "&INT((VALUE(RIGHT($A62,5))-1)/96)+1&": "&CHAR(65+INT(MOD(VALUE(RIGHT($A62,5))-1,96)/12))&(MOD(VALUE(RIGHT($A62,5))-1,12)+1))) | I62: =IF(NOT(AND($B62<>"",$C62<>"",$D62<>"",$E62<>"")),"",IF($A62="","","NIH plate "&INT((VALUE(RIGHT($A62,5))-1)/96)+1&": "&CHAR(65+INT(MOD(VALUE(RIGHT($A62,5))-1,96)/12))&(MOD(VALUE(RIGHT($A62,5))-1,12)+1))) | J62: =IF(NOT(AND($B62<>"",$C62<>"",$D62<>"",$E62<>"")),"",IF($A62="","","Max Planck plate "&INT((VALUE(RIGHT($A62,5))-1)/96)+1&": "&CHAR(65+INT(MOD(VALUE(RIGHT($A62,5))-1,96)/12))&(MOD(VALUE(RIGHT($A62,5))-1,12)+1))) | L62: =IF(OR(NOT(AND($B62<>"",$C62<>"",$D62<>"",$E62<>"")),$A62="",$K62<>"Yes"),"",IF($L62<>"",$L62,INDEX(SETUP!$I$1:$I$2000,MATCH(TRUE,SETUP!$J$1:$J$2000,0)+COUNTIFS($A$2:$A62,"<>",$K$2:$K62,"Yes",$L$2:$L62,"")-1)))
A63: =IF(COUNTA($B63:$E63,$K63)=0,"",IF(AND($B63<>"",$C63<>"",$D63<>"",$E63<>""),"TXS"&TEXT(COUNTIFS($B$2:$B63,"<>",$C$2:$C63,"<>",$D$2:$D63,"<>",$E$2:$E63,"<>"),"00000"),"")) | H63: =IF(NOT(AND($B63<>"",$C63<>"",$D63<>"",$E63<>"")),"",IF($A63="","","CDI plate "&INT((VALUE(RIGHT($A63,5))-1)/96)+1&": "&CHAR(65+INT(MOD(VALUE(RIGHT($A63,5))-1,96)/12))&(MOD(VALUE(RIGHT($A63,5))-1,12)+1))) | I63: =IF(NOT(AND($B63<>"",$C63<>"",$D63<>"",$E63<>"")),"",IF($A63="","","NIH plate "&INT((VALUE(RIGHT($A63,5))-1)/96)+1&": "&CHAR(65+INT(MOD(VALUE(RIGHT($A63,5))-1,96)/12))&(MOD(VALUE(RIGHT($A63,5))-1,12)+1))) | J63: =IF(NOT(AND($B63<>"",$C63<>"",$D63<>"",$E63<>"")),"",IF($A63="","","Max Planck plate "&INT((VALUE(RIGHT($A63,5))-1)/96)+1&": "&CHAR(65+INT(MOD(VALUE(RIGHT($A63,5))-1,96)/12))&(MOD(VALUE(RIGHT($A63,5))-1,12)+1))) | L63: =IF(OR(NOT(AND($B63<>"",$C63<>"",$D63<>"",$E63<>"")),$A63="",$K63<>"Yes"),"",IF($L63<>"",$L63,INDEX(SETUP!$I$1:$I$2000,MATCH(TRUE,SETUP!$J$1:$J$2000,0)+COUNTIFS($A$2:$A63,"<>",$K$2:$K63,"Yes",$L$2:$L63,"")-1)))
... A103: =IF(COUNTA($B103:$E103,$K103)=0,"",IF(AND($B103<>"",$C103<>"",$D103<>"",$E103<>""),"TXS"&TEXT(COUNTIFS($B$2:$B103,"<>",$C$2:$C103,"<>",$D$2:$D103,"<>",$E$2:$E103,"<>"),"00000"),"")) | H103: =IF(NOT(AND($B103<>"",$C103<>"",$D103<>"",$E103<>"")),"",IF($A103="","","CDI plate "&INT((VALUE(RIGHT($A103,5))-1)/96)+1&": "&CHAR(65+INT(MOD(VALUE(RIGHT($A103,5))-1,96)/12))&(MOD(VALUE(RIGHT($A103,5))-1,12)+1))) | I103: =IF(NOT(AND($B103<>"",$C103<>"",$D103<>"",$E103<>"")),"",IF($A103="","","NIH plate "&INT((VALUE(RIGHT($A103,5))-1)/96)+1&": "&CHAR(65+INT(MOD(VALUE(RIGHT($A103,5))-1,96)/12))&(MOD(VALUE(RIGHT($A103,5))-1,12)+1))) | J103: =IF(NOT(AND($B103<>"",$C103<>"",$D103<>"",$E103<>"")),"",IF($A103="","","Max Planck plate "&INT((VALUE(RIGHT($A103,5))-1)/96)+1&": "&CHAR(65+INT(MOD(VALUE(RIGHT($A103,5))-1,96)/12))&(MOD(VALUE(RIGHT($A103,5))-1,12)+1))) | L103: =IF(OR(NOT(AND($B103<>"",$C103<>"",$D103<>"",$E103<>"")),$A103="",$K103<>"Yes"),"",IF($L103<>"",$L103,INDEX(SETUP!$I$1:$I$2000,MATCH(TRUE,SETUP!$J$1:$J$2000,0)+COUNTIFS($A$2:$A103,"<>",$K$2:$K103,"Yes",$L$2:$L103,"")-1)))
A104: =IF(COUNTA($B104:$E104,$K104)=0,"",IF(AND($B104<>"",$C104<>"",$D104<>"",$E104<>""),"TXS"&TEXT(COUNTIFS($B$2:$B104,"<>",$C$2:$C104,"<>",$D$2:$D104,"<>",$E$2:$E104,"<>"),"00000"),"")) | H104: =IF(NOT(AND($B104<>"",$C104<>"",$D104<>"",$E104<>"")),"",IF($A104="","","CDI plate "&INT((VALUE(RIGHT($A104,5))-1)/96)+1&": "&CHAR(65+INT(MOD(VALUE(RIGHT($A104,5))-1,96)/12))&(MOD(VALUE(RIGHT($A104,5))-1,12)+1))) | J104: =IF(NOT(AND($B104<>"",$C104<>"",$D104<>"",$E104<>"")),"",IF($A104="","","Max Planck plate "&INT((VALUE(RIGHT($A104,5))-1)/96)+1&": "&CHAR(65+INT(MOD(VALUE(RIGHT($A104,5))-1,96)/12))&(MOD(VALUE(RIGHT($A104,5))-1,12)+1))) | L104: =IF(OR(NOT(AND($B104<>"",$C104<>"",$D104<>"",$E104<>"")),$A104="",$K104<>"Yes"),"",IF($L104<>"",$L104,INDEX(SETUP!$I$1:$I$2000,MATCH(TRUE,SETUP!$J$1:$J$2000,0)+COUNTIFS($A$2:$A104,"<>",$K$2:$K104,"Yes",$L$2:$L104,"")-1)))
A105: =IF(COUNTA($B105:$E105,$K105)=0,"",IF(AND($B105<>"",$C105<>"",$D105<>"",$E105<>""),"TXS"&TEXT(COUNTIFS($B$2:$B105,"<>",$C$2:$C105,"<>",$D$2:$D105,"<>",$E$2:$E105,"<>"),"00000"),"")) | H105: =IF(NOT(AND($B105<>"",$C105<>"",$D105<>"",$E105<>"")),"",IF($A105="","","CDI plate "&INT((VALUE(RIGHT($A105,5))-1)/96)+1&": "&CHAR(65+INT(MOD(VALUE(RIGHT($A105,5))-1,96)/12))&(MOD(VALUE(RIGHT($A105,5))-1,12)+1))) | I105: =IF(NOT(AND($B105<>"",$C105<>"",$D105<>"",$E105<>"")),"",IF($A105="","","NIH plate "&INT((VALUE(RIGHT($A105,5))-1)/96)+1&": "&CHAR(65+INT(MOD(VALUE(RIGHT($A105,5))-1,96)/12))&(MOD(VALUE(RIGHT($A105,5))-1,12)+1))) | J105: =IF(NOT(AND($B105<>"",$C105<>"",$D105<>"",$E105<>"")),"",IF($A105="","","Max Planck plate "&INT((VALUE(RIGHT($A105,5))-1)/96)+1&": "&CHAR(65+INT(MOD(VALUE(RIGHT($A105,5))-1,96)/12))&(MOD(VALUE(RIGHT($A105,5))-1,12)+1))) | L105: =IF(OR(NOT(AND($B105<>"",$C105<>"",$D105<>"",$E105<>"")),$A105="",$K105<>"Yes"),"",IF($L105<>"",$L105,INDEX(SETUP!$I$1:$I$2000,MATCH(TRUE,SETUP!$J$1:$J$2000,0)+COUNTIFS($A$2:$A105,"<>",$K$2:$K105,"Yes",$L$2:$L105,"")-1)))
A106: =IF(COUNTA($B106:$E106,$K106)=0,"",IF(AND($B106<>"",$C106<>"",$D106<>"",$E106<>""),"TXS"&TEXT(COUNTIFS($B$2:$B106,"<>",$C$2:$C106,"<>",$D$2:$D106,"<>",$E$2:$E106,"<>"),"00000"),"")) | H106: =IF(NOT(AND($B106<>"",$C106<>"",$D106<>"",$E106<>"")),"",IF($A106="","","CDI plate "&INT((VALUE(RIGHT($A106,5))-1)/96)+1&": "&CHAR(65+INT(MOD(VALUE(RIGHT($A106,5))-1,96)/12))&(MOD(VALUE(RIGHT($A106,5))-1,12)+1))) | I106: =IF(NOT(AND($B106<>"",$C106<>"",$D106<>"",$E106<>"")),"",IF($A106="","","NIH plate "&INT((VALUE(RIGHT($A106,5))-1)/96)+1&": "&CHAR(65+INT(MOD(VALUE(RIGHT($A106,5))-1,96)/12))&(MOD(VALUE(RIGHT($A106,5))-1,12)+1))) | J106: =IF(NOT(AND($B106<>"",$C106<>"",$D106<>"",$E106<>"")),"",IF($A106="","","Max Planck plate "&INT((VALUE(RIGHT($A106,5))-1)/96)+1&": "&CHAR(65+INT(MOD(VALUE(RIGHT($A106,5))-1,96)/12))&(MOD(VALUE(RIGHT($A106,5))-1,12)+1))) | L106: =IF(OR(NOT(AND($B106<>"",$C106<>"",$D106<>"",$E106<>"")),$A106="",$K106<>"Yes"),"",IF($L106<>"",$L106,INDEX(SETUP!$I$1:$I$2000,MATCH(TRUE,SETUP!$J$1:$J$2000,0)+COUNTIFS($A$2:$A106,"<>",$K$2:$K106,"Yes",$L$2:$L106,"")-1)))
A107: =IF(COUNTA($B107:$E107,$K107)=0,"",IF(AND($B107<>"",$C107<>"",$D107<>"",$E107<>""),"TXS"&TEXT(COUNTIFS($B$2:$B107,"<>",$C$2:$C107,"<>",$D$2:$D107,"<>",$E$2:$E107,"<>"),"00000"),"")) | H107: =IF(NOT(AND($B107<>"",$C107<>"",$D107<>"",$E107<>"")),"",IF($A107="","","CDI plate "&INT((VALUE(RIGHT($A107,5))-1)/96)+1&": "&CHAR(65+INT(MOD(VALUE(RIGHT($A107,5))-1,96)/12))&(MOD(VALUE(RIGHT($A107,5))-1,12)+1))) | I107: =IF(NOT(AND($B107<>"",$C107<>"",$D107<>"",$E107<>"")),"",IF($A107="","","NIH plate "&INT((VALUE(RIGHT($A107,5))-1)/96)+1&": "&CHAR(65+INT(MOD(VALUE(RIGHT($A107,5))-1,96)/12))&(MOD(VALUE(RIGHT($A107,5))-1,12)+1))) | L107: =IF(OR(NOT(AND($B107<>"",$C107<>"",$D107<>"",$E107<>"")),$A107="",$K107<>"Yes"),"",IF($L107<>"",$L107,INDEX(SETUP!$I$1:$I$2000,MATCH(TRUE,SETUP!$J$1:$J$2000,0)+COUNTIFS($A$2:$A107,"<>",$K$2:$K107,"Yes",$L$2:$L107,"")-1)))
A108: =IF(COUNTA($B108:$E108,$K108)=0,"",IF(AND($B108<>"",$C108<>"",$D108<>"",$E108<>""),"TXS"&TEXT(COUNTIFS($B$2:$B108,"<>",$C$2:$C108,"<>",$D$2:$D108,"<>",$E$2:$E108,"<>"),"00000"),"")) | H108: =IF(NOT(AND($B108<>"",$C108<>"",$D108<>"",$E108<>"")),"",IF($A108="","","CDI plate "&INT((VALUE(RIGHT($A108,5))-1)/96)+1&": "&CHAR(65+INT(MOD(VALUE(RIGHT($A108,5))-1,96)/12))&(MOD(VALUE(RIGHT($A108,5))-1,12)+1))) | I108: =IF(NOT(AND($B108<>"",$C108<>"",$D108<>"",$E108<>"")),"",IF($A108="","","NIH plate "&INT((VALUE(RIGHT($A108,5))-1)/96)+1&": "&CHAR(65+INT(MOD(VALUE(RIGHT($A108,5))-1,96)/12))&(MOD(VALUE(RIGHT($A108,5))-1,12)+1))) | J108: =IF(NOT(AND($B108<>"",$C108<>"",$D108<>"",$E108<>"")),"",IF($A108="","","Max Planck plate "&INT((VALUE(RIGHT($A108,5))-1)/96)+1&": "&CHAR(65+INT(MOD(VALUE(RIGHT($A108,5))-1,96)/12))&(MOD(VALUE(RIGHT($A108,5))-1,12)+1))) | L108: =IF(OR(NOT(AND($B108<>"",$C108<>"",$D108<>"",$E108<>"")),$A108="",$K108<>"Yes"),"",IF($L108<>"",$L108,INDEX(SETUP!$I$1:$I$2000,MATCH(TRUE,SETUP!$J$1:$J$2000,0)+COUNTIFS($A$2:$A108,"<>",$K$2:$K108,"Yes",$L$2:$L108,"")-1)))
A109: =IF(COUNTA($B109:$E109,$K109)=0,"",IF(AND($B109<>"",$C109<>"",$D109<>"",$E109<>""),"TXS"&TEXT(COUNTIFS($B$2:$B109,"<>",$C$2:$C109,"<>",$D$2:$D109,"<>",$E$2:$E109,"<>"),"00000"),"")) | H109: =IF(NOT(AND($B109<>"",$C109<>"",$D109<>"",$E109<>"")),"",IF($A109="","","CDI plate "&INT((VALUE(RIGHT($A109,5))-1)/96)+1&": "&CHAR(65+INT(MOD(VALUE(RIGHT($A109,5))-1,96)/12))&(MOD(VALUE(RIGHT($A109,5))-1,12)+1))) | I109: =IF(NOT(AND($B109<>"",$C109<>"",$D109<>"",$E109<>"")),"",IF($A109="","","NIH plate "&INT((VALUE(RIGHT($A109,5))-1)/96)+1&": "&CHAR(65+INT(MOD(VALUE(RIGHT($A109,5))-1,96)/12))&(MOD(VALUE(RIGHT($A109,5))-1,12)+1))) | J109: =IF(NOT(AND($B109<>"",$C109<>"",$D109<>"",$E109<>"")),"",IF($A109="","","Max Planck plate "&INT((VALUE(RIGHT($A109,5))-1)/96)+1&": "&CHAR(65+INT(MOD(VALUE(RIGHT($A109,5))-1,96)/12))&(MOD(VALUE(RIGHT($A109,5))-1,12)+1))) | L109: =IF(OR(NOT(AND($B109<>"",$C109<>"",$D109<>"",$E109<>"")),$A109="",$K109<>"Yes"),"",IF($L109<>"",$L109,INDEX(SETUP!$I$1:$I$2000,MATCH(TRUE,SETUP!$J$1:$J$2000,0)+COUNTIFS($A$2:$A109,"<>",$K$2:$K109,"Yes",$L$2:$L109,"")-1)))
A110: =IF(COUNTA($B110:$E110,$K110)=0,"",IF(AND($B110<>"",$C110<>"",$D110<>"",$E110<>""),"TXS"&TEXT(COUNTIFS($B$2:$B110,"<>",$C$2:$C110,"<>",$D$2:$D110,"<>",$E$2:$E110,"<>"),"00000"),"")) | H110: =IF(NOT(AND($B110<>"",$C110<>"",$D110<>"",$E110<>"")),"",IF($A110="","","CDI plate "&INT((VALUE(RIGHT($A110,5))-1)/96)+1&": "&CHAR(65+INT(MOD(VALUE(RIGHT($A110,5))-1,96)/12))&(MOD(VALUE(RIGHT($A110,5))-1,12)+1))) | I110: =IF(NOT(AND($B110<>"",$C110<>"",$D110<>"",$E110<>"")),"",IF($A110="","","NIH plate "&INT((VALUE(RIGHT($A110,5))-1)/96)+1&": "&CHAR(65+INT(MOD(VALUE(RIGHT($A110,5))-1,96)/12))&(MOD(VALUE(RIGHT($A110,5))-1,12)+1))) | J110: =IF(NOT(AND($B110<>"",$C110<>"",$D110<>"",$E110<>"")),"",IF($A110="","","Max Planck plate "&INT((VALUE(RIGHT($A110,5))-1)/96)+1&": "&CHAR(65+INT(MOD(VALUE(RIGHT($A110,5))-1,96)/12))&(MOD(VALUE(RIGHT($A110,5))-1,12)+1))) | L110: =IF(OR(NOT(AND($B110<>"",$C110<>"",$D110<>"",$E110<>"")),$A110="",$K110<>"Yes"),"",IF($L110<>"",$L110,INDEX(SETUP!$I$1:$I$2000,MATCH(TRUE,SETUP!$J$1:$J$2000,0)+COUNTIFS($A$2:$A110,"<>",$K$2:$K110,"Yes",$L$2:$L110,"")-1)))
...

Sheet CDI
B1: CDI plate 1
B2: 1 | C2: 2 | D2: 3 | E2: 4 | F2: 5 | G2: 6 | H2: 7 | I2: 8 | J2: 9 | K2: 10 | L2: 11 | M2: 12
A3: A | B3: =_xlfn.LET(_xlpm.pos,"CDI plate 1: "&$A3&B$2,_xlpm.normal,IFERROR(INDEX(MASTER!$A:$A,MATCH(_xlpm.pos,MASTER!$H:$H,0))&"_ser_0.20_"&TEXT(INDEX(MASTER!$E:$E,MATCH(_xlpm.pos,MASTER!$H:$H,0)),"mmddyy"),""),_xlpm.slot,(MATCH($A3,{"A","B","C","D","E","F","G","H"},0)-1)*12+B$2,_xlpm.code,"TXS"&TEXT(_xlpm.slot,"00000"),_xlpm.xval,IFERROR(_xlfn.XLOOKUP(_xlpm.code,MASTER!$A:$A,MASTER!$H:$H,""),""),IF(_xlpm.normal<>"",_xlpm.normal,IF(_xlpm.xval="X","X",""))) | C3: =_xlfn.LET(_xlpm.pos,"CDI plate 1: "&$A3&C$2,_xlpm.normal,IFERROR(INDEX(MASTER!$A:$A,MATCH(_xlpm.pos,MASTER!$H:$H,0))&"_ser_0.20_"&TEXT(INDEX(MASTER!$E:$E,MATCH(_xlpm.pos,MASTER!$H:$H,0)),"mmddyy"),""),_xlpm.slot,(MATCH($A3,{"A","B","C","D","E","F","G","H"},0)-1)*12+C$2,_xlpm.code,"TXS"&TEXT(_xlpm.slot,"00000"),_xlpm.xval,IFERROR(_xlfn.XLOOKUP(_xlpm.code,MASTER!$A:$A,MASTER!$H:$H,""),""),IF(_xlpm.normal<>"",_xlpm.normal,IF(_xlpm.xval="X","X",""))) | D3: =_xlfn.LET(_xlpm.pos,"CDI plate 1: "&$A3&D$2,_xlpm.normal,IFERROR(INDEX(MASTER!$A:$A,MATCH(_xlpm.pos,MASTER!$H:$H,0))&"_ser_0.20_"&TEXT(INDEX(MASTER!$E:$E,MATCH(_xlpm.pos,MASTER!$H:$H,0)),"mmddyy"),""),_xlpm.slot,(MATCH($A3,{"A","B","C","D","E","F","G","H"},0)-1)*12+D$2,_xlpm.code,"TXS"&TEXT(_xlpm.slot,"00000"),_xlpm.xval,IFERROR(_xlfn.XLOOKUP(_xlpm.code,MASTER!$A:$A,MASTER!$H:$H,""),""),IF(_xlpm.normal<>"",_xlpm.normal,IF(_xlpm.xval="X","X",""))) | E3: =_xlfn.LET(_xlpm.pos,"CDI plate 1: "&$A3&E$2,_xlpm.normal,IFERROR(INDEX(MASTER!$A:$A,MATCH(_xlpm.pos,MASTER!$H:$H,0))&"_ser_0.20_"&TEXT(INDEX(MASTER!$E:$E,MATCH(_xlpm.pos,MASTER!$H:$H,0)),"mmddyy"),""),_xlpm.slot,(MATCH($A3,{"A","B","C","D","E","F","G","H"},0)-1)*12+E$2,_xlpm.code,"TXS"&TEXT(_xlpm.slot,"00000"),_xlpm.xval,IFERROR(_xlfn.XLOOKUP(_xlpm.code,MASTER!$A:$A,MASTER!$H:$H,""),""),IF(_xlpm.normal<>"",_xlpm.normal,IF(_xlpm.xval="X","X",""))) | F3: =_xlfn.LET(_xlpm.pos,"CDI plate 1: "&$A3&F$2,_xlpm.normal,IFERROR(INDEX(MASTER!$A:$A,MATCH(_xlpm.pos,MASTER!$H:$H,0))&"_ser_0.20_"&TEXT(INDEX(MASTER!$E:$E,MATCH(_xlpm.pos,MASTER!$H:$H,0)),"mmddyy"),""),_xlpm.slot,(MATCH($A3,{"A","B","C","D","E","F","G","H"},0)-1)*12+F$2,_xlpm.code,"TXS"&TEXT(_xlpm.slot,"00000"),_xlpm.xval,IFERROR(_xlfn.XLOOKUP(_xlpm.code,MASTER!$A:$A,MASTER!$H:$H,""),""),IF(_xlpm.normal<>"",_xlpm.normal,IF(_xlpm.xval="X","X",""))) | G3: =_xlfn.LET(_xlpm.pos,"CDI plate 1: "&$A3&G$2,_xlpm.normal,IFERROR(INDEX(MASTER!$A:$A,MATCH(_xlpm.pos,MASTER!$H:$H,0))&"_ser_0.20_"&TEXT(INDEX(MASTER!$E:$E,MATCH(_xlpm.pos,MASTER!$H:$H,0)),"mmddyy"),""),_xlpm.slot,(MATCH($A3,{"A","B","C","D","E","F","G","H"},0)-1)*12+G$2,_xlpm.code,"TXS"&TEXT(_xlpm.slot,"00000"),_xlpm.xval,IFERROR(_xlfn.XLOOKUP(_xlpm.code,MASTER!$A:$A,MASTER!$H:$H,""),""),IF(_xlpm.normal<>"",_xlpm.normal,IF(_xlpm.xval="X","X",""))) | H3: =_xlfn.LET(_xlpm.pos,"CDI plate 1: "&$A3&H$2,_xlpm.normal,IFERROR(INDEX(MASTER!$A:$A,MATCH(_xlpm.pos,MASTER!$H:$H,0))&"_ser_0.20_"&TEXT(INDEX(MASTER!$E:$E,MATCH(_xlpm.pos,MASTER!$H:$H,0)),"mmddyy"),""),_xlpm.slot,(MATCH($A3,{"A","B","C","D","E","F","G","H"},0)-1)*12+H$2,_xlpm.code,"TXS"&TEXT(_xlpm.slot,"00000"),_xlpm.xval,IFERROR(_xlfn.XLOOKUP(_xlpm.code,MASTER!$A:$A,MASTER!$H:$H,""),""),IF(_xlpm.normal<>"",_xlpm.normal,IF(_xlpm.xval="X","X",""))) | I3: =_xlfn.LET(_xlpm.pos,"CDI plate 1: "&$A3&I$2,_xlpm.normal,IFERROR(INDEX(MASTER!$A:$A,MATCH(_xlpm.pos,MASTER!$H:$H,0))&"_ser_0.20_"&TEXT(INDEX(MASTER!$E:$E,MATCH(_xlpm.pos,MASTER!$H:$H,0)),"mmddyy"),""),_xlpm.slot,(MATCH($A3,{"A","B","C","D","E","F","G","H"},0)-1)*12+I$2,_xlpm.code,"TXS"&TEXT(_xlpm.slot,"00000"),_xlpm.xval,IFERROR(_xlfn.XLOOKUP(_xlpm.code,MASTER!$A:$A,MASTER!$H:$H,""),""),IF(_xlpm.normal<>"",_xlpm.normal,IF(_xlpm.xval="X","X",""))) | ... M3: =_xlfn.LET(_xlpm.pos,"CDI plate 1: "&$A3&M$2,_xlpm.normal,IFERROR(INDEX(MASTER!$A:$A,MATCH(_xlpm.pos,MASTER!$H:$H,0))&"_ser_0.20_"&TEXT(INDEX(MASTER!$E:$E,MATCH(_xlpm.pos,MASTER!$H:$H,0)),"mmddyy"),""),_xlpm.slot,(MATCH($A3,{"A","B","C","D","E","F","G","H"},0)-1)*12+M$2,_xlpm.code,"TXS"&TEXT(_xlpm.slot,"00000"),_xlpm.xval,IFERROR(_xlfn.XLOOKUP(_xlpm.code,MASTER!$A:$A,MASTER!$H:$H,""),""),IF(_xlpm.normal<>"",_xlpm.normal,IF(_xlpm.xval="X","X","")))
A4: B | B4: =_xlfn.LET(_xlpm.pos,"CDI plate 1: "&$A4&B$2,_xlpm.normal,IFERROR(INDEX(MASTER!$A:$A,MATCH(_xlpm.pos,MASTER!$H:$H,0))&"_ser_0.20_"&TEXT(INDEX(MASTER!$E:$E,MATCH(_xlpm.pos,MASTER!$H:$H,0)),"mmddyy"),""),_xlpm.slot,(MATCH($A4,{"A","B","C","D","E","F","G","H"},0)-1)*12+B$2,_xlpm.code,"TXS"&TEXT(_xlpm.slot,"00000"),_xlpm.xval,IFERROR(_xlfn.XLOOKUP(_xlpm.code,MASTER!$A:$A,MASTER!$H:$H,""),""),IF(_xlpm.normal<>"",_xlpm.normal,IF(_xlpm.xval="X","X",""))) | C4: =_xlfn.LET(_xlpm.pos,"CDI plate 1: "&$A4&C$2,_xlpm.normal,IFERROR(INDEX(MASTER!$A:$A,MATCH(_xlpm.pos,MASTER!$H:$H,0))&"_ser_0.20_"&TEXT(INDEX(MASTER!$E:$E,MATCH(_xlpm.pos,MASTER!$H:$H,0)),"mmddyy"),""),_xlpm.slot,(MATCH($A4,{"A","B","C","D","E","F","G","H"},0)-1)*12+C$2,_xlpm.code,"TXS"&TEXT(_xlpm.slot,"00000"),_xlpm.xval,IFERROR(_xlfn.XLOOKUP(_xlpm.code,MASTER!$A:$A,MASTER!$H:$H,""),""),IF(_xlpm.normal<>"",_xlpm.normal,IF(_xlpm.xval="X","X",""))) | D4: =_xlfn.LET(_xlpm.pos,"CDI plate 1: "&$A4&D$2,_xlpm.normal,IFERROR(INDEX(MASTER!$A:$A,MATCH(_xlpm.pos,MASTER!$H:$H,0))&"_ser_0.20_"&TEXT(INDEX(MASTER!$E:$E,MATCH(_xlpm.pos,MASTER!$H:$H,0)),"mmddyy"),""),_xlpm.slot,(MATCH($A4,{"A","B","C","D","E","F","G","H"},0)-1)*12+D$2,_xlpm.code,"TXS"&TEXT(_xlpm.slot,"00000"),_xlpm.xval,IFERROR(_xlfn.XLOOKUP(_xlpm.code,MASTER!$A:$A,MASTER!$H:$H,""),""),IF(_xlpm.normal<>"",_xlpm.normal,IF(_xlpm.xval="X","X",""))) | E4: =_xlfn.LET(_xlpm.pos,"CDI plate 1: "&$A4&E$2,_xlpm.normal,IFERROR(INDEX(MASTER!$A:$A,MATCH(_xlpm.pos,MASTER!$H:$H,0))&"_ser_0.20_"&TEXT(INDEX(MASTER!$E:$E,MATCH(_xlpm.pos,MASTER!$H:$H,0)),"mmddyy"),""),_xlpm.slot,(MATCH($A4,{"A","B","C","D","E","F","G","H"},0)-1)*12+E$2,_xlpm.code,"TXS"&TEXT(_xlpm.slot,"00000"),_xlpm.xval,IFERROR(_xlfn.XLOOKUP(_xlpm.code,MASTER!$A:$A,MASTER!$H:$H,""),""),IF(_xlpm.normal<>"",_xlpm.normal,IF(_xlpm.xval="X","X",""))) | F4: =_xlfn.LET(_xlpm.pos,"CDI plate 1: "&$A4&F$2,_xlpm.normal,IFERROR(INDEX(MASTER!$A:$A,MATCH(_xlpm.pos,MASTER!$H:$H,0))&"_ser_0.20_"&TEXT(INDEX(MASTER!$E:$E,MATCH(_xlpm.pos,MASTER!$H:$H,0)),"mmddyy"),""),_xlpm.slot,(MATCH($A4,{"A","B","C","D","E","F","G","H"},0)-1)*12+F$2,_xlpm.code,"TXS"&TEXT(_xlpm.slot,"00000"),_xlpm.xval,IFERROR(_xlfn.XLOOKUP(_xlpm.code,MASTER!$A:$A,MASTER!$H:$H,""),""),IF(_xlpm.normal<>"",_xlpm.normal,IF(_xlpm.xval="X","X",""))) | G4: =_xlfn.LET(_xlpm.pos,"CDI plate 1: "&$A4&G$2,_xlpm.normal,IFERROR(INDEX(MASTER!$A:$A,MATCH(_xlpm.pos,MASTER!$H:$H,0))&"_ser_0.20_"&TEXT(INDEX(MASTER!$E:$E,MATCH(_xlpm.pos,MASTER!$H:$H,0)),"mmddyy"),""),_xlpm.slot,(MATCH($A4,{"A","B","C","D","E","F","G","H"},0)-1)*12+G$2,_xlpm.code,"TXS"&TEXT(_xlpm.slot,"00000"),_xlpm.xval,IFERROR(_xlfn.XLOOKUP(_xlpm.code,MASTER!$A:$A,MASTER!$H:$H,""),""),IF(_xlpm.normal<>"",_xlpm.normal,IF(_xlpm.xval="X","X",""))) | H4: =_xlfn.LET(_xlpm.pos,"CDI plate 1: "&$A4&H$2,_xlpm.normal,IFERROR(INDEX(MASTER!$A:$A,MATCH(_xlpm.pos,MASTER!$H:$H,0))&"_ser_0.20_"&TEXT(INDEX(MASTER!$E:$E,MATCH(_xlpm.pos,MASTER!$H:$H,0)),"mmddyy"),""),_xlpm.slot,(MATCH($A4,{"A","B","C","D","E","F","G","H"},0)-1)*12+H$2,_xlpm.code,"TXS"&TEXT(_xlpm.slot,"00000"),_xlpm.xval,IFERROR(_xlfn.XLOOKUP(_xlpm.code,MASTER!$A:$A,MASTER!$H:$H,""),""),IF(_xlpm.normal<>"",_xlpm.normal,IF(_xlpm.xval="X","X",""))) | I4: =_xlfn.LET(_xlpm.pos,"CDI plate 1: "&$A4&I$2,_xlpm.normal,IFERROR(INDEX(MASTER!$A:$A,MATCH(_xlpm.pos,MASTER!$H:$H,0))&"_ser_0.20_"&TEXT(INDEX(MASTER!$E:$E,MATCH(_xlpm.pos,MASTER!$H:$H,0)),"mmddyy"),""),_xlpm.slot,(MATCH($A4,{"A","B","C","D","E","F","G","H"},0)-1)*12+I$2,_xlpm.code,"TXS"&TEXT(_xlpm.slot,"00000"),_xlpm.xval,IFERROR(_xlfn.XLOOKUP(_xlpm.code,MASTER!$A:$A,MASTER!$H:$H,""),""),IF(_xlpm.normal<>"",_xlpm.normal,IF(_xlpm.xval="X","X",""))) | ... M4: =_xlfn.LET(_xlpm.pos,"CDI plate 1: "&$A4&M$2,_xlpm.normal,IFERROR(INDEX(MASTER!$A:$A,MATCH(_xlpm.pos,MASTER!$H:$H,0))&"_ser_0.20_"&TEXT(INDEX(MASTER!$E:$E,MATCH(_xlpm.pos,MASTER!$H:$H,0)),"mmddyy"),""),_xlpm.slot,(MATCH($A4,{"A","B","C","D","E","F","G","H"},0)-1)*12+M$2,_xlpm.code,"TXS"&TEXT(_xlpm.slot,"00000"),_xlpm.xval,IFERROR(_xlfn.XLOOKUP(_xlpm.code,MASTER!$A:$A,MASTER!$H:$H,""),""),IF(_xlpm.normal<>"",_xlpm.normal,IF(_xlpm.xval="X","X","")))
A5: C | B5: =_xlfn.LET(_xlpm.pos,"CDI plate 1: "&$A5&B$2,_xlpm.normal,IFERROR(INDEX(MASTER!$A:$A,MATCH(_xlpm.pos,MASTER!$H:$H,0))&"_ser_0.20_"&TEXT(INDEX(MASTER!$E:$E,MATCH(_xlpm.pos,MASTER!$H:$H,0)),"mmddyy"),""),_xlpm.slot,(MATCH($A5,{"A","B","C","D","E","F","G","H"},0)-1)*12+B$2,_xlpm.code,"TXS"&TEXT(_xlpm.slot,"00000"),_xlpm.xval,IFERROR(_xlfn.XLOOKUP(_xlpm.code,MASTER!$A:$A,MASTER!$H:$H,""),""),IF(_xlpm.normal<>"",_xlpm.normal,IF(_xlpm.xval="X","X",""))) | C5: =_xlfn.LET(_xlpm.pos,"CDI plate 1: "&$A5&C$2,_xlpm.normal,IFERROR(INDEX(MASTER!$A:$A,MATCH(_xlpm.pos,MASTER!$H:$H,0))&"_ser_0.20_"&TEXT(INDEX(MASTER!$E:$E,MATCH(_xlpm.pos,MASTER!$H:$H,0)),"mmddyy"),""),_xlpm.slot,(MATCH($A5,{"A","B","C","D","E","F","G","H"},0)-1)*12+C$2,_xlpm.code,"TXS"&TEXT(_xlpm.slot,"00000"),_xlpm.xval,IFERROR(_xlfn.XLOOKUP(_xlpm.code,MASTER!$A:$A,MASTER!$H:$H,""),""),IF(_xlpm.normal<>"",_xlpm.normal,IF(_xlpm.xval="X","X",""))) | D5: =_xlfn.LET(_xlpm.pos,"CDI plate 1: "&$A5&D$2,_xlpm.normal,IFERROR(INDEX(MASTER!$A:$A,MATCH(_xlpm.pos,MASTER!$H:$H,0))&"_ser_0.20_"&TEXT(INDEX(MASTER!$E:$E,MATCH(_xlpm.pos,MASTER!$H:$H,0)),"mmddyy"),""),_xlpm.slot,(MATCH($A5,{"A","B","C","D","E","F","G","H"},0)-1)*12+D$2,_xlpm.code,"TXS"&TEXT(_xlpm.slot,"00000"),_xlpm.xval,IFERROR(_xlfn.XLOOKUP(_xlpm.code,MASTER!$A:$A,MASTER!$H:$H,""),""),IF(_xlpm.normal<>"",_xlpm.normal,IF(_xlpm.xval="X","X",""))) | E5: =_xlfn.LET(_xlpm.pos,"CDI plate 1: "&$A5&E$2,_xlpm.normal,IFERROR(INDEX(MASTER!$A:$A,MATCH(_xlpm.pos,MASTER!$H:$H,0))&"_ser_0.20_"&TEXT(INDEX(MASTER!$E:$E,MATCH(_xlpm.pos,MASTER!$H:$H,0)),"mmddyy"),""),_xlpm.slot,(MATCH($A5,{"A","B","C","D","E","F","G","H"},0)-1)*12+E$2,_xlpm.code,"TXS"&TEXT(_xlpm.slot,"00000"),_xlpm.xval,IFERROR(_xlfn.XLOOKUP(_xlpm.code,MASTER!$A:$A,MASTER!$H:$H,""),""),IF(_xlpm.normal<>"",_xlpm.normal,IF(_xlpm.xval="X","X",""))) | F5: =_xlfn.LET(_xlpm.pos,"CDI plate 1: "&$A5&F$2,_xlpm.normal,IFERROR(INDEX(MASTER!$A:$A,MATCH(_xlpm.pos,MASTER!$H:$H,0))&"_ser_0.20_"&TEXT(INDEX(MASTER!$E:$E,MATCH(_xlpm.pos,MASTER!$H:$H,0)),"mmddyy"),""),_xlpm.slot,(MATCH($A5,{"A","B","C","D","E","F","G","H"},0)-1)*12+F$2,_xlpm.code,"TXS"&TEXT(_xlpm.slot,"00000"),_xlpm.xval,IFERROR(_xlfn.XLOOKUP(_xlpm.code,MASTER!$A:$A,MASTER!$H:$H,""),""),IF(_xlpm.normal<>"",_xlpm.normal,IF(_xlpm.xval="X","X",""))) | G5: =_xlfn.LET(_xlpm.pos,"CDI plate 1: "&$A5&G$2,_xlpm.normal,IFERROR(INDEX(MASTER!$A:$A,MATCH(_xlpm.pos,MASTER!$H:$H,0))&"_ser_0.20_"&TEXT(INDEX(MASTER!$E:$E,MATCH(_xlpm.pos,MASTER!$H:$H,0)),"mmddyy"),""),_xlpm.slot,(MATCH($A5,{"A","B","C","D","E","F","G","H"},0)-1)*12+G$2,_xlpm.code,"TXS"&TEXT(_xlpm.slot,"00000"),_xlpm.xval,IFERROR(_xlfn.XLOOKUP(_xlpm.code,MASTER!$A:$A,MASTER!$H:$H,""),""),IF(_xlpm.normal<>"",_xlpm.normal,IF(_xlpm.xval="X","X",""))) | H5: =_xlfn.LET(_xlpm.pos,"CDI plate 1: "&$A5&H$2,_xlpm.normal,IFERROR(INDEX(MASTER!$A:$A,MATCH(_xlpm.pos,MASTER!$H:$H,0))&"_ser_0.20_"&TEXT(INDEX(MASTER!$E:$E,MATCH(_xlpm.pos,MASTER!$H:$H,0)),"mmddyy"),""),_xlpm.slot,(MATCH($A5,{"A","B","C","D","E","F","G","H"},0)-1)*12+H$2,_xlpm.code,"TXS"&TEXT(_xlpm.slot,"00000"),_xlpm.xval,IFERROR(_xlfn.XLOOKUP(_xlpm.code,MASTER!$A:$A,MASTER!$H:$H,""),""),IF(_xlpm.normal<>"",_xlpm.normal,IF(_xlpm.xval="X","X",""))) | I5: =_xlfn.LET(_xlpm.pos,"CDI plate 1: "&$A5&I$2,_xlpm.normal,IFERROR(INDEX(MASTER!$A:$A,MATCH(_xlpm.pos,MASTER!$H:$H,0))&"_ser_0.20_"&TEXT(INDEX(MASTER!$E:$E,MATCH(_xlpm.pos,MASTER!$H:$H,0)),"mmddyy"),""),_xlpm.slot,(MATCH($A5,{"A","B","C","D","E","F","G","H"},0)-1)*12+I$2,_xlpm.code,"TXS"&TEXT(_xlpm.slot,"00000"),_xlpm.xval,IFERROR(_xlfn.XLOOKUP(_xlpm.code,MASTER!$A:$A,MASTER!$H:$H,""),""),IF(_xlpm.normal<>"",_xlpm.normal,IF(_xlpm.xval="X","X",""))) | ... M5: =_xlfn.LET(_xlpm.pos,"CDI plate 1: "&$A5&M$2,_xlpm.normal,IFERROR(INDEX(MASTER!$A:$A,MATCH(_xlpm.pos,MASTER!$H:$H,0))&"_ser_0.20_"&TEXT(INDEX(MASTER!$E:$E,MATCH(_xlpm.pos,MASTER!$H:$H,0)),"mmddyy"),""),_xlpm.slot,(MATCH($A5,{"A","B","C","D","E","F","G","H"},0)-1)*12+M$2,_xlpm.code,"TXS"&TEXT(_xlpm.slot,"00000"),_xlpm.xval,IFERROR(_xlfn.XLOOKUP(_xlpm.code,MASTER!$A:$A,MASTER!$H:$H,""),""),IF(_xlpm.normal<>"",_xlpm.normal,IF(_xlpm.xval="X","X","")))
A6: D | B6: =_xlfn.LET(_xlpm.pos,"CDI plate 1: "&$A6&B$2,_xlpm.normal,IFERROR(INDEX(MASTER!$A:$A,MATCH(_xlpm.pos,MASTER!$H:$H,0))&"_ser_0.20_"&TEXT(INDEX(MASTER!$E:$E,MATCH(_xlpm.pos,MASTER!$H:$H,0)),"mmddyy"),""),_xlpm.slot,(MATCH($A6,{"A","B","C","D","E","F","G","H"},0)-1)*12+B$2,_xlpm.code,"TXS"&TEXT(_xlpm.slot,"00000"),_xlpm.xval,IFERROR(_xlfn.XLOOKUP(_xlpm.code,MASTER!$A:$A,MASTER!$H:$H,""),""),IF(_xlpm.normal<>"",_xlpm.normal,IF(_xlpm.xval="X","X",""))) | C6: =_xlfn.LET(_xlpm.pos,"CDI plate 1: "&$A6&C$2,_xlpm.normal,IFERROR(INDEX(MASTER!$A:$A,MATCH(_xlpm.pos,MASTER!$H:$H,0))&"_ser_0.20_"&TEXT(INDEX(MASTER!$E:$E,MATCH(_xlpm.pos,MASTER!$H:$H,0)),"mmddyy"),""),_xlpm.slot,(MATCH($A6,{"A","B","C","D","E","F","G","H"},0)-1)*12+C$2,_xlpm.code,"TXS"&TEXT(_xlpm.slot,"00000"),_xlpm.xval,IFERROR(_xlfn.XLOOKUP(_xlpm.code,MASTER!$A:$A,MASTER!$H:$H,""),""),IF(_xlpm.normal<>"",_xlpm.normal,IF(_xlpm.xval="X","X",""))) | D6: =_xlfn.LET(_xlpm.pos,"CDI plate 1: "&$A6&D$2,_xlpm.normal,IFERROR(INDEX(MASTER!$A:$A,MATCH(_xlpm.pos,MASTER!$H:$H,0))&"_ser_0.20_"&TEXT(INDEX(MASTER!$E:$E,MATCH(_xlpm.pos,MASTER!$H:$H,0)),"mmddyy"),""),_xlpm.slot,(MATCH($A6,{"A","B","C","D","E","F","G","H"},0)-1)*12+D$2,_xlpm.code,"TXS"&TEXT(_xlpm.slot,"00000"),_xlpm.xval,IFERROR(_xlfn.XLOOKUP(_xlpm.code,MASTER!$A:$A,MASTER!$H:$H,""),""),IF(_xlpm.normal<>"",_xlpm.normal,IF(_xlpm.xval="X","X",""))) | E6: =_xlfn.LET(_xlpm.pos,"CDI plate 1: "&$A6&E$2,_xlpm.normal,IFERROR(INDEX(MASTER!$A:$A,MATCH(_xlpm.pos,MASTER!$H:$H,0))&"_ser_0.20_"&TEXT(INDEX(MASTER!$E:$E,MATCH(_xlpm.pos,MASTER!$H:$H,0)),"mmddyy"),""),_xlpm.slot,(MATCH($A6,{"A","B","C","D","E","F","G","H"},0)-1)*12+E$2,_xlpm.code,"TXS"&TEXT(_xlpm.slot,"00000"),_xlpm.xval,IFERROR(_xlfn.XLOOKUP(_xlpm.code,MASTER!$A:$A,MASTER!$H:$H,""),""),IF(_xlpm.normal<>"",_xlpm.normal,IF(_xlpm.xval="X","X",""))) | F6: =_xlfn.LET(_xlpm.pos,"CDI plate 1: "&$A6&F$2,_xlpm.normal,IFERROR(INDEX(MASTER!$A:$A,MATCH(_xlpm.pos,MASTER!$H:$H,0))&"_ser_0.20_"&TEXT(INDEX(MASTER!$E:$E,MATCH(_xlpm.pos,MASTER!$H:$H,0)),"mmddyy"),""),_xlpm.slot,(MATCH($A6,{"A","B","C","D","E","F","G","H"},0)-1)*12+F$2,_xlpm.code,"TXS"&TEXT(_xlpm.slot,"00000"),_xlpm.xval,IFERROR(_xlfn.XLOOKUP(_xlpm.code,MASTER!$A:$A,MASTER!$H:$H,""),""),IF(_xlpm.normal<>"",_xlpm.normal,IF(_xlpm.xval="X","X",""))) | G6: =_xlfn.LET(_xlpm.pos,"CDI plate 1: "&$A6&G$2,_xlpm.normal,IFERROR(INDEX(MASTER!$A:$A,MATCH(_xlpm.pos,MASTER!$H:$H,0))&"_ser_0.20_"&TEXT(INDEX(MASTER!$E:$E,MATCH(_xlpm.pos,MASTER!$H:$H,0)),"mmddyy"),""),_xlpm.slot,(MATCH($A6,{"A","B","C","D","E","F","G","H"},0)-1)*12+G$2,_xlpm.code,"TXS"&TEXT(_xlpm.slot,"00000"),_xlpm.xval,IFERROR(_xlfn.XLOOKUP(_xlpm.code,MASTER!$A:$A,MASTER!$H:$H,""),""),IF(_xlpm.normal<>"",_xlpm.normal,IF(_xlpm.xval="X","X",""))) | H6: =_xlfn.LET(_xlpm.pos,"CDI plate 1: "&$A6&H$2,_xlpm.normal,IFERROR(INDEX(MASTER!$A:$A,MATCH(_xlpm.pos,MASTER!$H:$H,0))&"_ser_0.20_"&TEXT(INDEX(MASTER!$E:$E,MATCH(_xlpm.pos,MASTER!$H:$H,0)),"mmddyy"),""),_xlpm.slot,(MATCH($A6,{"A","B","C","D","E","F","G","H"},0)-1)*12+H$2,_xlpm.code,"TXS"&TEXT(_xlpm.slot,"00000"),_xlpm.xval,IFERROR(_xlfn.XLOOKUP(_xlpm.code,MASTER!$A:$A,MASTER!$H:$H,""),""),IF(_xlpm.normal<>"",_xlpm.normal,IF(_xlpm.xval="X","X",""))) | I6: =_xlfn.LET(_xlpm.pos,"CDI plate 1: "&$A6&I$2,_xlpm.normal,IFERROR(INDEX(MASTER!$A:$A,MATCH(_xlpm.pos,MASTER!$H:$H,0))&"_ser_0.20_"&TEXT(INDEX(MASTER!$E:$E,MATCH(_xlpm.pos,MASTER!$H:$H,0)),"mmddyy"),""),_xlpm.slot,(MATCH($A6,{"A","B","C","D","E","F","G","H"},0)-1)*12+I$2,_xlpm.code,"TXS"&TEXT(_xlpm.slot,"00000"),_xlpm.xval,IFERROR(_xlfn.XLOOKUP(_xlpm.code,MASTER!$A:$A,MASTER!$H:$H,""),""),IF(_xlpm.normal<>"",_xlpm.normal,IF(_xlpm.xval="X","X",""))) | ... M6: =_xlfn.LET(_xlpm.pos,"CDI plate 1: "&$A6&M$2,_xlpm.normal,IFERROR(INDEX(MASTER!$A:$A,MATCH(_xlpm.pos,MASTER!$H:$H,0))&"_ser_0.20_"&TEXT(INDEX(MASTER!$E:$E,MATCH(_xlpm.pos,MASTER!$H:$H,0)),"mmddyy"),""),_xlpm.slot,(MATCH($A6,{"A","B","C","D","E","F","G","H"},0)-1)*12+M$2,_xlpm.code,"TXS"&TEXT(_xlpm.slot,"00000"),_xlpm.xval,IFERROR(_xlfn.XLOOKUP(_xlpm.code,MASTER!$A:$A,MASTER!$H:$H,""),""),IF(_xlpm.normal<>"",_xlpm.normal,IF(_xlpm.xval="X","X","")))
